Workbook

Sheet सारांश
A1: BPSC 1.5 वर्षीय अध्ययन योजना (15 नवंबर 2026 → 14 मई 2028)
A2: प्रारंभिक + मुख्य परीक्षा की तैयारी • दिन-वार, सप्ताह-वार व माह-वार • हर विषय के लिए सैद्धांतिक रूपरेखा, नोट्स स्रोत व YouTube लिंक
A4: योजना आरंभ तिथि (आवश्यकता हो तो बदलें) | B4: 46341 | E4: ← 15 नवंबर 2026 रविवार है = दिन 1 (शुभारंभ)। सप्ताह 16 नवंबर से सोम–रवि चलते हैं। तिथि बदलें तो रविवार ही रखें।
A5: योजना समाप्ति तिथि | B5: =B4+546 -> 46887
A6: कुल दिन / सप्ताह / माह | B6: =B5-B4+1 -> 547 | C6: =ROUNDDOWN((B6-1)/7,0) -> 78 | D6: 18
A8: प्रगति डैशबोर्ड
A9: चरण | B9: सप्ताह | C9: आरंभ तिथि | D9: समाप्ति तिथि | E9: नियोजित दिन | F9: पूर्ण दिन | G9: पूर्णता %
A10: शुभारंभ दिवस | B10: दिन 1 | C10: =$B$4 -> 46341 | D10: =$B$4 -> 46341 | E10: =COUNTIF('दैनिक योजना'!$F$6:$F$552,A10) -> 1 | F10: =COUNTIFS('दैनिक योजना'!$F$6:$F$552,A10,'दैनिक योजना'!$W$6:$W$552,"पूर्ण")+COUNTIFS('दैनिक योजना'!$F$6:$F$552,A10,'दैनिक योजना'!$W$6:$W$552,"दोहराया") -> 0 | G10: =IFERROR(F10/E10,0) -> 0
A11: चरण 1: आधार निर्माण (प्रथम अध्ययन) | B11: 1–26 | C11: =$B$4+1+7*0 -> 46342 | D11: =$B$4+7*26 -> 46523 | E11: =COUNTIF('दैनिक योजना'!$F$6:$F$552,A11) -> 182 | F11: =COUNTIFS('दैनिक योजना'!$F$6:$F$552,A11,'दैनिक योजना'!$W$6:$W$552,"पूर्ण")+COUNTIFS('दैनिक योजना'!$F$6:$F$552,A11,'दैनिक योजना'!$W$6:$W$552,"दोहराया") -> 0 | G11: =IFERROR(F11/E11,0) -> 0
A12: चरण 2: उन्नत अध्ययन + मुख्य परीक्षा कौशल (द्वितीय अध्ययन) | B12: 27–52 | C12: =$B$4+1+7*26 -> 46524 | D12: =$B$4+7*52 -> 46705 | E12: =COUNTIF('दैनिक योजना'!$F$6:$F$552,A12) -> 182 | F12: =COUNTIFS('दैनिक योजना'!$F$6:$F$552,A12,'दैनिक योजना'!$W$6:$W$552,"पूर्ण")+COUNTIFS('दैनिक योजना'!$F$6:$F$552,A12,'दैनिक योजना'!$W$6:$W$552,"दोहराया") -> 0 | G12: =IFERROR(F12/E12,0) -> 0
A13: चरण 3A: पुनरावृत्ति चक्र + PYQ | B13: 53–66 | C13: =$B$4+1+7*52 -> 46706 | D13: =$B$4+7*66 -> 46803 | E13: =COUNTIF('दैनिक योजना'!$F$6:$F$552,A13) -> 98 | F13: =COUNTIFS('दैनिक योजना'!$F$6:$F$552,A13,'दैनिक योजना'!$W$6:$W$552,"पूर्ण")+COUNTIFS('दैनिक योजना'!$F$6:$F$552,A13,'दैनिक योजना'!$W$6:$W$552,"दोहराया") -> 0 | G13: =IFERROR(F13/E13,0) -> 0
A14: चरण 3B: टेस्ट सीरीज़ एवं कमज़ोर क्षेत्र सुधार | B14: 67–74 | C14: =$B$4+1+7*66 -> 46804 | D14: =$B$4+7*74 -> 46859 | E14: =COUNTIF('दैनिक योजना'!$F$6:$F$552,A14) -> 56 | F14: =COUNTIFS('दैनिक योजना'!$F$6:$F$552,A14,'दैनिक योजना'!$W$6:$W$552,"पूर्ण")+COUNTIFS('दैनिक योजना'!$F$6:$F$552,A14,'दैनिक योजना'!$W$6:$W$552,"दोहराया") -> 0 | G14: =IFERROR(F14/E14,0) -> 0
A15: चरण 3C: अंतिम मॉक एवं पुनरावृत्ति | B15: 75–78 | C15: =$B$4+1+7*74 -> 46860 | D15: =$B$4+7*78 -> 46887 | E15: =COUNTIF('दैनिक योजना'!$F$6:$F$552,A15) -> 28 | F15: =COUNTIFS('दैनिक योजना'!$F$6:$F$552,A15,'दैनिक योजना'!$W$6:$W$552,"पूर्ण")+COUNTIFS('दैनिक योजना'!$F$6:$F$552,A15,'दैनिक योजना'!$W$6:$W$552,"दोहराया") -> 0 | G15: =IFERROR(F15/E15,0) -> 0
A16: कुल | E16: =SUM(E10:E15) -> 547 | F16: =SUM(F10:F15) -> 0 | G16: =IFERROR(F16/E16,0) -> 0
A18: बीते दिन (आज तक) | B18: =MAX(0,MIN(TODAY()-B4+1,B6)) -> 0
A19: आज तक अपेक्षित पूर्णता | B19: =IFERROR(B18/B6,0) -> 0
A20: आपकी वास्तविक पूर्णता | B20: =G16 -> 0
A21: आगे / (पीछे) – दिनों में | B21: =F16-B18 -> 0
A23: 18 माह की योजना कैसे बनी है
A24: • चरण 1 (सप्ताह 1–26, नवंबर 2026–मई 2027): सभी सामान्य अध्ययन विषयों का प्रथम अध्ययन – इतिहास, भूगोल, राजव्यवस्था, अर्थव्यवस्था, पर्यावरण (प्राथमिक 3 घंटे) तथा बिहार विशेष, विज्ञान, गणित-तर्कशक्ति व हिंदी (द्वितीयक 2 घंटे)। पहले NCERT, फिर मानक पुस्तक/कोचिंग नोट्स।
A25: • चरण 2 (सप्ताह 27–52, मई–नवंबर 2027): उन्हीं विषयों का द्वितीय, उन्नत अध्ययन + PYQ; बिहार गहन अध्ययन; गणित-तर्कशक्ति की गति का अभ्यास; मुख्य परीक्षा उत्तर लेखन, निबंध व बिहार के समसामयिक मुद्दे।
A26: • चरण 3A (सप्ताह 53–66): विषय-वार पुनरावृत्ति चक्र, प्रतिदिन 60 PYQ MCQ। चरण 3B (सप्ताह 67–74): सोम–शुक्र सेक्शनल टेस्ट, हर शनिवार पूर्ण मॉक, कमज़ोर क्षेत्र सुधार। चरण 3C (सप्ताह 75–78): प्रतिदिन पूर्ण मॉक / मुख्य परीक्षा टेस्ट, अंतिम संक्षिप्त नोट्स पुनरावृत्ति, अंतिम सप्ताह हल्का व विश्राम।
A27: • प्रतिदिन: 1 घंटा करेंट अफेयर्स (घूमता विषय) + 1 घंटा अभ्यास + 0.5 घंटा पुनरावृत्ति। प्रत्येक रविवार: टेस्ट + साप्ताहिक पुनरावृत्ति। हर चौथा रविवार: 150 प्रश्नों का मासिक टेस्ट।
A28: • घंटे: अपनी दिनचर्या अलग हो तो 'दैनिक योजना' में 'अध्ययन घंटे' कॉलम बदलें। दैनिक योजना (कॉलम W) में 'स्थिति' भरें – साप्ताहिक, मासिक व यह डैशबोर्ड अपने-आप अपडेट होंगे।
A30: महत्वपूर्ण मान्यताएँ एवं टिप्पणियाँ
A31: • पाठ्यक्रम व पैटर्न: योजना में प्रारंभिक परीक्षा के सामान्य अध्ययन (इतिहास, भूगोल, राजव्यवस्था, अर्थव्यवस्था, विज्ञान, पर्यावरण, बिहार विशेष, गणित/मानसिक योग्यता, करेंट अफेयर्स) तथा मुख्य परीक्षा के सामान्य अध्ययन/हिंदी/निबंध कौशल शामिल हैं। BPSC का पैटर्न हर अधिसूचना में बदल सकता है – bpsc.bihar.gov.in पर नवीनतम पाठ्यक्रम से मिलान अवश्य करें।
A32: • परीक्षा तिथि: योजना मानती है कि परीक्षा 14 मई 2028 के कुछ ही बाद होगी। अधिसूचना पहले आए तो चरण 2/3 छोटे करें; बाद में आए तो चरण 3B/3C के मॉक बढ़ाएँ।
A33: • YouTube लिंक: हर लिंक 'विषय + कोचिंग चैनल' की YouTube खोज है (दृष्टि IAS, BPSC वाला, विजन IAS, EduTeria)। अलग-अलग वीडियो के URL की पुष्टि संभव नहीं थी, इसलिए गलत/टूटे लिंक से बचने के लिए खोज लिंक दिए गए हैं – खोलकर नवीनतम पूर्ण व्याख्यान या प्लेलिस्ट चुनें।
A34: • सैद्धांतिक नोट्स: कोचिंग (दृष्टि, विजन IAS, BPSC वाला आदि) के नोट्स सशुल्क/कॉपीराइट वाले हैं, इसलिए यहाँ कॉपी नहीं किए गए। हर विषय के लिए 'सैद्धांतिक मुख्य बिंदु' (क्या पढ़ना है) + उन्हें पढ़ने के सटीक नोट्स/पुस्तकें दी गई हैं (विषय सूची शीट व दैनिक योजना के नोट्स कॉलम)।
A35: • करेंट अफेयर्स: पिछले 12 महीनों के मासिक संकलन (दृष्टि IAS / विजन IAS) नियमित दोहराएँ – यह दैनिक 1 घंटे के CA स्लॉट व रविवार के संकलन में शामिल है।
A37: रंग संकेत: पीला सेल = इनपुट • नीला/हरा/पीला/नारंगी/बैंगनी पट्टियाँ = चरण • दैनिक योजना में नारंगी पंक्ति = रविवार टेस्ट दिवस • हरी पंक्ति = पूर्ण।

Sheet मासिक योजना
A1: मासिक योजना – 18 माह
A2: प्रत्येक माह 15 तारीख से अगले माह की 14 तारीख तक चलता है। पूर्णता दैनिक योजना की 'स्थिति' से स्वतः गणना होती है।
A5: माह # | B5: से | C5: तक | D5: चरण | E5: प्राथमिक फोकस (विषय) | F5: द्वितीयक फोकस (विषय) | G5: मासिक लक्ष्य एवं उपलब्धियाँ | H5: मासिक टेस्ट | I5: नियोजित दिन | J5: पूर्ण दिन | K5: पूर्णता %
A6: 1 | B6: =EDATE(सारांश!$B$4,A6-1) -> 46341 | C6: =EDATE(सारांश!$B$4,A6)-1 -> 46370 | D6: शुभारंभ दिवस चरण 1: आधार निर्माण (प्रथम अध्ययन) | E6: प्रारंभिक दिशा-निर्देश; प्रागैतिहास एवं सिंधु घाटी सभ्यता; वैदिक काल एवं महाजनपद; जैन, बौद्ध एवं अन्य नास्तिक संप्रदाय; मौर्य साम्राज्य; मौर्योत्तर काल (शुंग, कुषाण, सातवाहन, संगम); गुप्त साम्राज्य, हर्षवर्धन एवं पाल वंश; पूर्व मध्यकालीन भारत (राजपूत, चोल, चालुक्य, पल्लव); दिल्ली सल्तनत; भक्ति एवं सूफी आंदोलन; मुगल साम्राज्य | F6: योजना; बिहार – प्राचीन इतिहास; बिहार – मध्यकालीन एवं औपनिवेशिक इतिहास; बिहार – स्वतंत्रता संग्राम एवं आधुनिक राजनीति; बिहार – भूगोल: भौतिक स्वरूप, नदियाँ एवं जलवायु; बिहार – कृषि, सिंचाई एवं उद्योग | G6: सप्ताह 1–5। सूचीबद्ध हर विषय नोट्स + 50 MCQ के साथ पूरा करें; त्रुटि-लॉग रखें; मासिक टेस्ट ≥ 55%। | H6: मासिक टेस्ट: 150 प्रश्न, प्रारंभिक परीक्षा पैटर्न (माह का अंतिम रविवार) + विश्लेषण | I6: =COUNTIF('दैनिक योजना'!$E$6:$E$552,A6) -> 30 | J6: =COUNTIFS('दैनिक योजना'!$E$6:$E$552,A6,'दैनिक योजना'!$W$6:$W$552,"पूर्ण")+COUNTIFS('दैनिक योजना'!$E$6:$E$552,A6,'दैनिक योजना'!$W$6:$W$552,"दोहराया") -> 0 | K6: =IFERROR(J6/I6,0) -> 0
A7: 2 | B7: =EDATE(सारांश!$B$4,A7-1) -> 46371 | C7: =EDATE(सारांश!$B$4,A7)-1 -> 46401 | D7: चरण 1: आधार निर्माण (प्रथम अध्ययन) | E7: मुगल साम्राज्य; मराठा एवं क्षेत्रीय शक्तियाँ (18वीं शताब्दी); यूरोपीय आगमन एवं ब्रिटिश विस्तार; 1857 का विद्रोह; सामाजिक-धार्मिक सुधार आंदोलन; प्रारंभिक राष्ट्रवाद: कांग्रेस, नरमपंथी, गरमपंथी, स्वदेशी; गांधी युग: चंपारण से भारत छोड़ो तक; क्रांतिकारी आंदोलन, संवैधानिक विकास एवं विभाजन; स्वातंत्र्योत्तर भारत (1947 के बाद); भारतीय कला एवं स्थापत्य; प्रदर्शन कलाएँ, साहित्य, त्योहार एवं यूनेस्को स्थल; ब्रह्मांड, सौरमंडल एवं पृथ्वी | F7: बिहार – कृषि, सिंचाई एवं उद्योग; बिहार – अर्थव्यवस्था, बजट एवं सरकारी योजनाएँ; बिहार – राजव्यवस्था एवं प्रशासन; बिहार – कला, संस्कृति, साहित्य एवं पर्यटन; बिहार – जनसांख्यिकी, शिक्षा एवं स्वास्थ्य; भौतिकी I: गति, बल, कार्य एवं गुरुत्वाकर्षण | G7: सप्ताह 5–9। सूचीबद्ध हर विषय नोट्स + 50 MCQ के साथ पूरा करें; त्रुटि-लॉग रखें; मासिक टेस्ट ≥ 55%। | H7: मासिक टेस्ट: 150 प्रश्न, प्रारंभिक परीक्षा पैटर्न (माह का अंतिम रविवार) + विश्लेषण | I7: =COUNTIF('दैनिक योजना'!$E$6:$E$552,A7) -> 31 | J7: =COUNTIFS('दैनिक योजना'!$E$6:$E$552,A7,'दैनिक योजना'!$W$6:$W$552,"पूर्ण")+COUNTIFS('दैनिक योजना'!$E$6:$E$552,A7,'दैनिक योजना'!$W$6:$W$552,"दोहराया") -> 0 | K7: =IFERROR(J7/I7,0) -> 0
A8: 3 | B8: =EDATE(सारांश!$B$4,A8-1) -> 46402 | C8: =EDATE(सारांश!$B$4,A8)-1 -> 46432 | D8: चरण 1: आधार निर्माण (प्रथम अध्ययन) | E8: ब्रह्मांड, सौरमंडल एवं पृथ्वी; भू-आकृति विज्ञान: पृथ्वी का आंतरिक भाग, चट्टानें एवं स्थलरूप; जलवायु विज्ञान: वायुमंडल, पवनें एवं जलवायु; समुद्र विज्ञान; भारत का भौतिक स्वरूप; भारतीय अपवाह तंत्र; भारत की जलवायु, मानसून, मृदा एवं वनस्पति; भारतीय कृषि; खनिज, ऊर्जा एवं उद्योग | F8: भौतिकी I: गति, बल, कार्य एवं गुरुत्वाकर्षण; भौतिकी II: ऊष्मा, प्रकाश, ध्वनि, विद्युत एवं आधुनिक भौतिकी; रसायन I: पदार्थ, परमाणु, आवर्त सारणी एवं अम्ल-क्षार; रसायन II: धातु, कार्बन यौगिक एवं दैनिक जीवन में रसायन; जीव विज्ञान I: कोशिका, पादप एवं जंतु जगत | G8: सप्ताह 9–13। सूचीबद्ध हर विषय नोट्स + 50 MCQ के साथ पूरा करें; त्रुटि-लॉग रखें; मासिक टेस्ट ≥ 55%। | H8: मासिक टेस्ट: 150 प्रश्न, प्रारंभिक परीक्षा पैटर्न (माह का अंतिम रविवार) + विश्लेषण | I8: =COUNTIF('दैनिक योजना'!$E$6:$E$552,A8) -> 31 | J8: =COUNTIFS('दैनिक योजना'!$E$6:$E$552,A8,'दैनिक योजना'!$W$6:$W$552,"पूर्ण")+COUNTIFS('दैनिक योजना'!$E$6:$E$552,A8,'दैनिक योजना'!$W$6:$W$552,"दोहराया") -> 0 | K8: =IFERROR(J8/I8,0) -> 0
A9: 4 | B9: =EDATE(सारांश!$B$4,A9-1) -> 46433 | C9: =EDATE(सारांश!$B$4,A9)-1 -> 46460 | D9: चरण 1: आधार निर्माण (प्रथम अध्ययन) | E9: खनिज, ऊर्जा एवं उद्योग; परिवहन, जनसंख्या, जनगणना एवं नगरीकरण; विश्व भूगोल; संविधान निर्माण, प्रस्तावना एवं विशेषताएँ; संघ, नागरिकता एवं मौलिक अधिकार; नीति निदेशक तत्व, मौलिक कर्तव्य एवं संविधान संशोधन; संघ की कार्यपालिका; संसद | F9: जीव विज्ञान II: मानव शरीर, पोषण एवं रोग; विज्ञान एवं प्रौद्योगिकी: अंतरिक्ष, रक्षा, IT एवं उभरती तकनीकें; गणित I: संख्या पद्धति, म.स.-ल.स. एवं सरलीकरण; गणित II: प्रतिशत, लाभ-हानि, अनुपात एवं औसत | G9: सप्ताह 14–17। सूचीबद्ध हर विषय नोट्स + 50 MCQ के साथ पूरा करें; त्रुटि-लॉग रखें; मासिक टेस्ट ≥ 55%। | H9: मासिक टेस्ट: 150 प्रश्न, प्रारंभिक परीक्षा पैटर्न (माह का अंतिम रविवार) + विश्लेषण | I9: =COUNTIF('दैनिक योजना'!$E$6:$E$552,A9) -> 28 | J9: =COUNTIFS('दैनिक योजना'!$E$6:$E$552,A9,'दैनिक योजना'!$W$6:$W$552,"पूर्ण")+COUNTIFS('दैनिक योजना'!$E$6:$E$552,A9,'दैनिक योजना'!$W$6:$W$552,"दोहराया") -> 0 | K9: =IFERROR(J9/I9,0) -> 0
A10: 5 | B10: =EDATE(सारांश!$B$4,A10-1) -> 46461 | C10: =EDATE(सारांश!$B$4,A10)-1 -> 46491 | D10: चरण 1: आधार निर्माण (प्रथम अध्ययन) | E10: संसद; न्यायपालिका; संघवाद: केंद्र–राज्य संबंध एवं आपातकाल; राज्य सरकार, पंचायती राज एवं नगरपालिकाएँ; संवैधानिक एवं गैर-संवैधानिक निकाय; शासन, अधिकार एवं सामाजिक न्याय; मूल अवधारणाएँ, राष्ट्रीय आय एवं मुद्रास्फीति; नियोजन, गरीबी एवं बेरोज़गारी; मुद्रा, बैंकिंग एवं मौद्रिक नीति | F10: गणित II: प्रतिशत, लाभ-हानि, अनुपात एवं औसत; गणित III: समय-कार्य, समय-चाल-दूरी एवं ब्याज; गणित IV: बीजगणित, ज्यामिति, क्षेत्रमिति एवं त्रिकोणमिति; गणित V: आँकड़ा व्याख्या एवं सांख्यिकी; तर्कशक्ति I: श्रेणी, कोडिंग-डिकोडिंग एवं सादृश्य | G10: सप्ताह 18–22। सूचीबद्ध हर विषय नोट्स + 50 MCQ के साथ पूरा करें; त्रुटि-लॉग रखें; मासिक टेस्ट ≥ 55%। | H10: मासिक टेस्ट: 150 प्रश्न, प्रारंभिक परीक्षा पैटर्न (माह का अंतिम रविवार) + विश्लेषण | I10: =COUNTIF('दैनिक योजना'!$E$6:$E$552,A10) -> 31 | J10: =COUNTIFS('दैनिक योजना'!$E$6:$E$552,A10,'दैनिक योजना'!$W$6:$W$552,"पूर्ण")+COUNTIFS('दैनिक योजना'!$E$6:$E$552,A10,'दैनिक योजना'!$W$6:$W$552,"दोहराया") -> 0 | K10: =IFERROR(J10/I10,0) -> 0
A11: 6 | B11: =EDATE(सारांश!$B$4,A11-1) -> 46492 | C11: =EDATE(सारांश!$B$4,A11)-1 -> 46521 | D11: चरण 1: आधार निर्माण (प्रथम अध्ययन) | E11: मुद्रा, बैंकिंग एवं मौद्रिक नीति; सार्वजनिक वित्त: बजट, कराधान एवं GST; कृषि अर्थव्यवस्था; उद्योग, सेवाएँ एवं अवसंरचना; बाह्य क्षेत्र एवं अंतर्राष्ट्रीय संस्थाएँ; पूँजी बाज़ार, बीमा, आर्थिक सर्वेक्षण एवं बजट; पारिस्थितिकी एवं पारितंत्र; जैव विविधता एवं संरक्षण; जलवायु परिवर्तन, प्रदूषण एवं पर्यावरण कानून | F11: तर्कशक्ति I: श्रेणी, कोडिंग-डिकोडिंग एवं सादृश्य; तर्कशक्ति II: दिशा, रक्त संबंध, न्यायवाक्य एवं पहेलियाँ; हिंदी व्याकरण I: वर्ण, संधि, समास, उपसर्ग-प्रत्यय; हिंदी व्याकरण II: वाक्य शुद्धि, मुहावरे, पर्यायवाची; हिंदी लेखन: गद्यांश, पत्र, निबंध एवं अनुवाद | G11: सप्ताह 22–26। सूचीबद्ध हर विषय नोट्स + 50 MCQ के साथ पूरा करें; त्रुटि-लॉग रखें; मासिक टेस्ट ≥ 55%। | H11: मासिक टेस्ट: 150 प्रश्न, प्रारंभिक परीक्षा पैटर्न (माह का अंतिम रविवार) + विश्लेषण | I11: =COUNTIF('दैनिक योजना'!$E$6:$E$552,A11) -> 30 | J11: =COUNTIFS('दैनिक योजना'!$E$6:$E$552,A11,'दैनिक योजना'!$W$6:$W$552,"पूर्ण")+COUNTIFS('दैनिक योजना'!$E$6:$E$552,A11,'दैनिक योजना'!$W$6:$W$552,"दोहराया") -> 0 | K11: =IFERROR(J11/I11,0) -> 0
A12: 7 | B12: =EDATE(सारांश!$B$4,A12-1) -> 46522 | C12: =EDATE(सारांश!$B$4,A12)-1 -> 46552 | D12: चरण 1: आधार निर्माण (प्रथम अध्ययन) चरण 2: उन्नत अध्ययन + मुख्य परीक्षा कौशल (द्वितीय अध्ययन) | E12: जलवायु परिवर्तन, प्रदूषण एवं पर्यावरण कानून; प्रागैतिहास एवं सिंधु घाटी सभ्यता; वैदिक काल एवं महाजनपद; जैन, बौद्ध एवं अन्य नास्तिक संप्रदाय; मौर्य साम्राज्य; मौर्योत्तर काल (शुंग, कुषाण, सातवाहन, संगम); गुप्त साम्राज्य, हर्षवर्धन एवं पाल वंश; पूर्व मध्यकालीन भारत (राजपूत, चोल, चालुक्य, पल्लव); दिल्ली सल्तनत; भक्ति एवं सूफी आंदोलन; मुगल साम्राज्य | F12: हिंदी लेखन: गद्यांश, पत्र, निबंध एवं अनुवाद; बिहार – प्राचीन इतिहास; बिहार – मध्यकालीन एवं औपनिवेशिक इतिहास; बिहार – स्वतंत्रता संग्राम एवं आधुनिक राजनीति; बिहार – भूगोल: भौतिक स्वरूप, नदियाँ एवं जलवायु; बिहार – कृषि, सिंचाई एवं उद्योग; बिहार – अर्थव्यवस्था, बजट एवं सरकारी योजनाएँ | G12: सप्ताह 26–31। सूचीबद्ध हर विषय नोट्स + 50 MCQ के साथ पूरा करें; त्रुटि-लॉग रखें; मासिक टेस्ट ≥ 65%। | H12: मासिक टेस्ट: 150 प्रश्न, प्रारंभिक परीक्षा पैटर्न (माह का अंतिम रविवार) + विश्लेषण | I12: =COUNTIF('दैनिक योजना'!$E$6:$E$552,A12) -> 31 | J12: =COUNTIFS('दैनिक योजना'!$E$6:$E$552,A12,'दैनिक योजना'!$W$6:$W$552,"पूर्ण")+COUNTIFS('दैनिक योजना'!$E$6:$E$552,A12,'दैनिक योजना'!$W$6:$W$552,"दोहराया") -> 0 | K12: =IFERROR(J12/I12,0) -> 0
A13: 8 | B13: =EDATE(सारांश!$B$4,A13-1) -> 46553 | C13: =EDATE(सारांश!$B$4,A13)-1 -> 46582 | D13: चरण 2: उन्नत अध्ययन + मुख्य परीक्षा कौशल (द्वितीय अध्ययन) | E13: मुगल साम्राज्य; मराठा एवं क्षेत्रीय शक्तियाँ (18वीं शताब्दी); यूरोपीय आगमन एवं ब्रिटिश विस्तार; 1857 का विद्रोह; सामाजिक-धार्मिक सुधार आंदोलन; प्रारंभिक राष्ट्रवाद: कांग्रेस, नरमपंथी, गरमपंथी, स्वदेशी; गांधी युग: चंपारण से भारत छोड़ो तक; क्रांतिकारी आंदोलन, संवैधानिक विकास एवं विभाजन; स्वातंत्र्योत्तर भारत (1947 के बाद); भारतीय कला एवं स्थापत्य; प्रदर्शन कलाएँ, साहित्य, त्योहार एवं यूनेस्को स्थल | F13: बिहार – अर्थव्यवस्था, बजट एवं सरकारी योजनाएँ; बिहार – राजव्यवस्था एवं प्रशासन; बिहार – कला, संस्कृति, साहित्य एवं पर्यटन; बिहार – जनसांख्यिकी, शिक्षा एवं स्वास्थ्य; गणित I: संख्या पद्धति, म.स.-ल.स. एवं सरलीकरण; गणित II: प्रतिशत, लाभ-हानि, अनुपात एवं औसत; गणित III: समय-कार्य, समय-चाल-दूरी एवं ब्याज | G13: सप्ताह 31–35। सूचीबद्ध हर विषय नोट्स + 50 MCQ के साथ पूरा करें; त्रुटि-लॉग रखें; मासिक टेस्ट ≥ 65%। | H13: मासिक टेस्ट: 150 प्रश्न, प्रारंभिक परीक्षा पैटर्न (माह का अंतिम रविवार) + विश्लेषण | I13: =COUNTIF('दैनिक योजना'!$E$6:$E$552,A13) -> 30 | J13: =COUNTIFS('दैनिक योजना'!$E$6:$E$552,A13,'दैनिक योजना'!$W$6:$W$552,"पूर्ण")+COUNTIFS('दैनिक योजना'!$E$6:$E$552,A13,'दैनिक योजना'!$W$6:$W$552,"दोहराया") -> 0 | K13: =IFERROR(J13/I13,0) -> 0
A14: 9 | B14: =EDATE(सारांश!$B$4,A14-1) -> 46583 | C14: =EDATE(सारांश!$B$4,A14)-1 -> 46613 | D14: चरण 2: उन्नत अध्ययन + मुख्य परीक्षा कौशल (द्वितीय अध्ययन) | E14: ब्रह्मांड, सौरमंडल एवं पृथ्वी; भू-आकृति विज्ञान: पृथ्वी का आंतरिक भाग, चट्टानें एवं स्थलरूप; जलवायु विज्ञान: वायुमंडल, पवनें एवं जलवायु; समुद्र विज्ञान; भारत का भौतिक स्वरूप; भारतीय अपवाह तंत्र; भारत की जलवायु, मानसून, मृदा एवं वनस्पति; भारतीय कृषि; खनिज, ऊर्जा एवं उद्योग | F14: गणित III: समय-कार्य, समय-चाल-दूरी एवं ब्याज; गणित IV: बीजगणित, ज्यामिति, क्षेत्रमिति एवं त्रिकोणमिति; गणित V: आँकड़ा व्याख्या एवं सांख्यिकी; तर्कशक्ति I: श्रेणी, कोडिंग-डिकोडिंग एवं सादृश्य; तर्कशक्ति II: दिशा, रक्त संबंध, न्यायवाक्य एवं पहेलियाँ; उत्तर लेखन की मूल बातें: संरचना, भूमिका-मुख्य भाग-निष्कर्ष | G14: सप्ताह 35–39। सूचीबद्ध हर विषय नोट्स + 50 MCQ के साथ पूरा करें; त्रुटि-लॉग रखें; मासिक टेस्ट ≥ 65%। | H14: मासिक टेस्ट: 150 प्रश्न, प्रारंभिक परीक्षा पैटर्न (माह का अंतिम रविवार) + विश्लेषण | I14: =COUNTIF('दैनिक योजना'!$E$6:$E$552,A14) -> 31 | J14: =COUNTIFS('दैनिक योजना'!$E$6:$E$552,A14,'दैनिक योजना'!$W$6:$W$552,"पूर्ण")+COUNTIFS('दैनिक योजना'!$E$6:$E$552,A14,'दैनिक योजना'!$W$6:$W$552,"दोहराया") -> 0 | K14: =IFERROR(J14/I14,0) -> 0
A15: 10 | B15: =EDATE(सारांश!$B$4,A15-1) -> 46614 | C15: =EDATE(सारांश!$B$4,A15)-1 -> 46644 | D15: चरण 2: उन्नत अध्ययन + मुख्य परीक्षा कौशल (द्वितीय अध्ययन) | E15: खनिज, ऊर्जा एवं उद्योग; परिवहन, जनसंख्या, जनगणना एवं नगरीकरण; विश्व भूगोल; संविधान निर्माण, प्रस्तावना एवं विशेषताएँ; संघ, नागरिकता एवं मौलिक अधिकार; नीति निदेशक तत्व, मौलिक कर्तव्य एवं संविधान संशोधन; संघ की कार्यपालिका; संसद; न्यायपालिका | F15: उत्तर लेखन की मूल बातें: संरचना, भूमिका-मुख्य भाग-निष्कर्ष; उत्तर लेखन – इतिहास एवं संस्कृति; उत्तर लेखन – भूगोल एवं आपदा प्रबंधन; उत्तर लेखन – राजव्यवस्था, शासन एवं सामाजिक न्याय; उत्तर लेखन – अर्थव्यवस्था एवं बिहार की अर्थव्यवस्था | G15: सप्ताह 39–44। सूचीबद्ध हर विषय नोट्स + 50 MCQ के साथ पूरा करें; त्रुटि-लॉग रखें; मासिक टेस्ट ≥ 65%। | H15: मासिक टेस्ट: 150 प्रश्न, प्रारंभिक परीक्षा पैटर्न (माह का अंतिम रविवार) + विश्लेषण | I15: =COUNTIF('दैनिक योजना'!$E$6:$E$552,A15) -> 31 | J15: =COUNTIFS('दैनिक योजना'!$E$6:$E$552,A15,'दैनिक योजना'!$W$6:$W$552,"पूर्ण")+COUNTIFS('दैनिक योजना'!$E$6:$E$552,A15,'दैनिक योजना'!$W$6:$W$552,"दोहराया") -> 0 | K15: =IFERROR(J15/I15,0) -> 0
A16: 11 | B16: =EDATE(सारांश!$B$4,A16-1) -> 46645 | C16: =EDATE(सारांश!$B$4,A16)-1 -> 46674 | D16: चरण 2: उन्नत अध्ययन + मुख्य परीक्षा कौशल (द्वितीय अध्ययन) | E16: न्यायपालिका; संघवाद: केंद्र–राज्य संबंध एवं आपातकाल; राज्य सरकार, पंचायती राज एवं नगरपालिकाएँ; संवैधानिक एवं गैर-संवैधानिक निकाय; शासन, अधिकार एवं सामाजिक न्याय; मूल अवधारणाएँ, राष्ट्रीय आय एवं मुद्रास्फीति; नियोजन, गरीबी एवं बेरोज़गारी; मुद्रा, बैंकिंग एवं मौद्रिक नीति | F16: उत्तर लेखन – अर्थव्यवस्था एवं बिहार की अर्थव्यवस्था; उत्तर लेखन – विज्ञान, प्रौद्योगिकी एवं पर्यावरण; बिहार के समसामयिक मुद्दे: बाढ़, प्रवासन, शिक्षा, स्वास्थ्य, औद्योगीकरण; सामाजिक मुद्दे एवं समसामयिक विषय | G16: सप्ताह 44–48। सूचीबद्ध हर विषय नोट्स + 50 MCQ के साथ पूरा करें; त्रुटि-लॉग रखें; मासिक टेस्ट ≥ 65%। | H16: मासिक टेस्ट: 150 प्रश्न, प्रारंभिक परीक्षा पैटर्न (माह का अंतिम रविवार) + विश्लेषण | I16: =COUNTIF('दैनिक योजना'!$E$6:$E$552,A16) -> 30 | J16: =COUNTIFS('दैनिक योजना'!$E$6:$E$552,A16,'दैनिक योजना'!$W$6:$W$552,"पूर्ण")+COUNTIFS('दैनिक योजना'!$E$6:$E$552,A16,'दैनिक योजना'!$W$6:$W$552,"दोहराया") -> 0 | K16: =IFERROR(J16/I16,0) -> 0
A17: 12 | B17: =EDATE(सारांश!$B$4,A17-1) -> 46675 | C17: =EDATE(सारांश!$B$4,A17)-1 -> 46705 | D17: चरण 2: उन्नत अध्ययन + मुख्य परीक्षा कौशल (द्वितीय अध्ययन) | E17: मुद्रा, बैंकिंग एवं मौद्रिक नीति; सार्वजनिक वित्त: बजट, कराधान एवं GST; कृषि अर्थव्यवस्था; उद्योग, सेवाएँ एवं अवसंरचना; बाह्य क्षेत्र एवं अंतर्राष्ट्रीय संस्थाएँ; पूँजी बाज़ार, बीमा, आर्थिक सर्वेक्षण एवं बजट; पारिस्थितिकी एवं पारितंत्र; जैव विविधता एवं संरक्षण; जलवायु परिवर्तन, प्रदूषण एवं पर्यावरण कानून | F17: सामाजिक मुद्दे एवं समसामयिक विषय; अंतर्राष्ट्रीय संबंध एवं आंतरिक सुरक्षा; निबंध लेखन अभ्यास (हिंदी/अंग्रेज़ी); हिंदी मुख्य परीक्षा: संक्षेपण, पत्र, अनुवाद एवं व्याकरण; केस स्टडी, नैतिकता एवं ईमानदारी की मूल बातें | G17: सप्ताह 48–52। सूचीबद्ध हर विषय नोट्स + 50 MCQ के साथ पूरा करें; त्रुटि-लॉग रखें; मासिक टेस्ट ≥ 65%। | H17: मासिक टेस्ट: 150 प्रश्न, प्रारंभिक परीक्षा पैटर्न (माह का अंतिम रविवार) + विश्लेषण | I17: =COUNTIF('दैनिक योजना'!$E$6:$E$552,A17) -> 31 | J17: =COUNTIFS('दैनिक योजना'!$E$6:$E$552,A17,'दैनिक योजना'!$W$6:$W$552,"पूर्ण")+COUNTIFS('दैनिक योजना'!$E$6:$E$552,A17,'दैनिक योजना'!$W$6:$W$552,"दोहराया") -> 0 | K17: =IFERROR(J17/I17,0) -> 0
... A23: 18 | B23: =EDATE(सारांश!$B$4,A23-1) -> 46858 | C23: =EDATE(सारांश!$B$4,A23)-1 -> 46887 | D23: चरण 3B: टेस्ट सीरीज़ एवं कमज़ोर क्षेत्र सुधार चरण 3C: अंतिम मॉक एवं पुनरावृत्ति | E23: टेस्ट सीरीज़; अंतिम पुनरावृत्ति | F23: कमज़ोर क्षेत्र सुधार; अंतिम पुनरावृत्ति | G23: सप्ताह 74–78। सूचीबद्ध हर विषय नोट्स + 50 MCQ के साथ पूरा करें; त्रुटि-लॉग रखें; मासिक टेस्ट ≥ 85%। | H23: मासिक टेस्ट: 150 प्रश्न, प्रारंभिक परीक्षा पैटर्न (माह का अंतिम रविवार) + विश्लेषण | I23: =COUNTIF('दैनिक योजना'!$E$6:$E$552,A23) -> 30 | J23: =COUNTIFS('दैनिक योजना'!$E$6:$E$552,A23,'दैनिक योजना'!$W$6:$W$552,"पूर्ण")+COUNTIFS('दैनिक योजना'!$E$6:$E$552,A23,'दैनिक योजना'!$W$6:$W$552,"दोहराया") -> 0 | K23: =IFERROR(J23/I23,0) -> 0

Sheet साप्ताहिक योजना
A1: साप्ताहिक योजना – 78 सप्ताह (+ शुभारंभ दिवस)
A2: तिथियाँ 'सारांश' शीट की आरंभ तिथि से अपने-आप बनती हैं। अपना साप्ताहिक टेस्ट स्कोर कॉलम L में दर्ज करें।
A5: सप्ताह # | B5: आरंभ (सोम) | C5: समाप्त (रवि) | D5: माह # | E5: चरण | F5: प्राथमिक विषय (सोम–शनि) | G5: द्वितीयक विषय (सोम–शनि) | H5: रविवार टेस्ट | I5: साप्ताहिक लक्ष्य | J5: पूर्ण दिन | K5: पूर्णता % | L5: टेस्ट स्कोर % | M5: टिप्पणी
A6: 0 | B6: =सारांश!$B$4 -> 46341 | C6: =B6 -> 46341 | D6: =(YEAR(B6)-YEAR(सारांश!$B$4))*12+MONTH(B6)-MONTH(सारांश!$B$4)+IF(DAY(B6)>=DAY(सारांश!$B$4),1,0) -> 1 | E6: शुभारंभ दिवस | F6: शुभारंभ: पाठ्यक्रम, PYQ, डायग्नोस्टिक टेस्ट, नोट्स की व्यवस्था | G6: योजना व ट्रैकर की स्थापना | H6: — (डायग्नोस्टिक टेस्ट उसी दिन) | I6: पैटर्न समझें; कमज़ोर विषय पहचानें | J6: =COUNTIFS('दैनिक योजना'!$D$6:$D$552,A6,'दैनिक योजना'!$W$6:$W$552,"पूर्ण")+COUNTIFS('दैनिक योजना'!$D$6:$D$552,A6,'दैनिक योजना'!$W$6:$W$552,"दोहराया") -> 0 | K6: =IFERROR(J6/COUNTIF('दैनिक योजना'!$D$6:$D$552,A6),0) -> 0
A7: 1 | B7: =सारांश!$B$4+1+7*(A7-1) -> 46342 | C7: =B7+6 -> 46348 | D7: =(YEAR(B7)-YEAR(सारांश!$B$4))*12+MONTH(B7)-MONTH(सारांश!$B$4)+IF(DAY(B7)>=DAY(सारांश!$B$4),1,0) -> 1 | E7: चरण 1: आधार निर्माण (प्रथम अध्ययन) | F7: प्रागैतिहास एवं सिंधु घाटी सभ्यता; वैदिक काल एवं महाजनपद | G7: बिहार – प्राचीन इतिहास; बिहार – मध्यकालीन एवं औपनिवेशिक इतिहास | H7: साप्ताहिक टेस्ट (100 MCQ, 90 मिनट) + विश्लेषण | I7: सूचीबद्ध सभी विषय पूरे करें; ~300 MCQ; साप्ताहिक टेस्ट ≥ 55% | J7: =COUNTIFS('दैनिक योजना'!$D$6:$D$552,A7,'दैनिक योजना'!$W$6:$W$552,"पूर्ण")+COUNTIFS('दैनिक योजना'!$D$6:$D$552,A7,'दैनिक योजना'!$W$6:$W$552,"दोहराया") -> 0 | K7: =IFERROR(J7/COUNTIF('दैनिक योजना'!$D$6:$D$552,A7),0) -> 0
A8: 2 | B8: =सारांश!$B$4+1+7*(A8-1) -> 46349 | C8: =B8+6 -> 46355 | D8: =(YEAR(B8)-YEAR(सारांश!$B$4))*12+MONTH(B8)-MONTH(सारांश!$B$4)+IF(DAY(B8)>=DAY(सारांश!$B$4),1,0) -> 1 | E8: चरण 1: आधार निर्माण (प्रथम अध्ययन) | F8: जैन, बौद्ध एवं अन्य नास्तिक संप्रदाय; मौर्य साम्राज्य; मौर्योत्तर काल (शुंग, कुषाण, सातवाहन, संगम) | G8: बिहार – मध्यकालीन एवं औपनिवेशिक इतिहास; बिहार – स्वतंत्रता संग्राम एवं आधुनिक राजनीति | H8: साप्ताहिक टेस्ट (100 MCQ, 90 मिनट) + विश्लेषण | I8: सूचीबद्ध सभी विषय पूरे करें; ~300 MCQ; साप्ताहिक टेस्ट ≥ 55% | J8: =COUNTIFS('दैनिक योजना'!$D$6:$D$552,A8,'दैनिक योजना'!$W$6:$W$552,"पूर्ण")+COUNTIFS('दैनिक योजना'!$D$6:$D$552,A8,'दैनिक योजना'!$W$6:$W$552,"दोहराया") -> 0 | K8: =IFERROR(J8/COUNTIF('दैनिक योजना'!$D$6:$D$552,A8),0) -> 0
A9: 3 | B9: =सारांश!$B$4+1+7*(A9-1) -> 46356 | C9: =B9+6 -> 46362 | D9: =(YEAR(B9)-YEAR(सारांश!$B$4))*12+MONTH(B9)-MONTH(सारांश!$B$4)+IF(DAY(B9)>=DAY(सारांश!$B$4),1,0) -> 1 | E9: चरण 1: आधार निर्माण (प्रथम अध्ययन) | F9: गुप्त साम्राज्य, हर्षवर्धन एवं पाल वंश; पूर्व मध्यकालीन भारत (राजपूत, चोल, चालुक्य, पल्लव); दिल्ली सल्तनत | G9: बिहार – स्वतंत्रता संग्राम एवं आधुनिक राजनीति; बिहार – भूगोल: भौतिक स्वरूप, नदियाँ एवं जलवायु | H9: साप्ताहिक टेस्ट (100 MCQ, 90 मिनट) + विश्लेषण | I9: सूचीबद्ध सभी विषय पूरे करें; ~300 MCQ; साप्ताहिक टेस्ट ≥ 55% | J9: =COUNTIFS('दैनिक योजना'!$D$6:$D$552,A9,'दैनिक योजना'!$W$6:$W$552,"पूर्ण")+COUNTIFS('दैनिक योजना'!$D$6:$D$552,A9,'दैनिक योजना'!$W$6:$W$552,"दोहराया") -> 0 | K9: =IFERROR(J9/COUNTIF('दैनिक योजना'!$D$6:$D$552,A9),0) -> 0
A10: 4 | B10: =सारांश!$B$4+1+7*(A10-1) -> 46363 | C10: =B10+6 -> 46369 | D10: =(YEAR(B10)-YEAR(सारांश!$B$4))*12+MONTH(B10)-MONTH(सारांश!$B$4)+IF(DAY(B10)>=DAY(सारांश!$B$4),1,0) -> 1 | E10: चरण 1: आधार निर्माण (प्रथम अध्ययन) | F10: दिल्ली सल्तनत; भक्ति एवं सूफी आंदोलन; मुगल साम्राज्य | G10: बिहार – भूगोल: भौतिक स्वरूप, नदियाँ एवं जलवायु; बिहार – कृषि, सिंचाई एवं उद्योग | H10: मासिक टेस्ट (150 प्रश्न, 2 घंटे, प्रारंभिक परीक्षा पैटर्न) + विश्लेषण + आधे दिन का विश्राम | I10: सूचीबद्ध सभी विषय पूरे करें; ~300 MCQ; साप्ताहिक टेस्ट ≥ 55% | J10: =COUNTIFS('दैनिक योजना'!$D$6:$D$552,A10,'दैनिक योजना'!$W$6:$W$552,"पूर्ण")+COUNTIFS('दैनिक योजना'!$D$6:$D$552,A10,'दैनिक योजना'!$W$6:$W$552,"दोहराया") -> 0 | K10: =IFERROR(J10/COUNTIF('दैनिक योजना'!$D$6:$D$552,A10),0) -> 0
A11: 5 | B11: =सारांश!$B$4+1+7*(A11-1) -> 46370 | C11: =B11+6 -> 46376 | D11: =(YEAR(B11)-YEAR(सारांश!$B$4))*12+MONTH(B11)-MONTH(सारांश!$B$4)+IF(DAY(B11)>=DAY(सारांश!$B$4),1,0) -> 1 | E11: चरण 1: आधार निर्माण (प्रथम अध्ययन) | F11: मुगल साम्राज्य; मराठा एवं क्षेत्रीय शक्तियाँ (18वीं शताब्दी); यूरोपीय आगमन एवं ब्रिटिश विस्तार | G11: बिहार – कृषि, सिंचाई एवं उद्योग; बिहार – अर्थव्यवस्था, बजट एवं सरकारी योजनाएँ | H11: साप्ताहिक टेस्ट (100 MCQ, 90 मिनट) + विश्लेषण | I11: सूचीबद्ध सभी विषय पूरे करें; ~300 MCQ; साप्ताहिक टेस्ट ≥ 55% | J11: =COUNTIFS('दैनिक योजना'!$D$6:$D$552,A11,'दैनिक योजना'!$W$6:$W$552,"पूर्ण")+COUNTIFS('दैनिक योजना'!$D$6:$D$552,A11,'दैनिक योजना'!$W$6:$W$552,"दोहराया") -> 0 | K11: =IFERROR(J11/COUNTIF('दैनिक योजना'!$D$6:$D$552,A11),0) -> 0
A12: 6 | B12: =सारांश!$B$4+1+7*(A12-1) -> 46377 | C12: =B12+6 -> 46383 | D12: =(YEAR(B12)-YEAR(सारांश!$B$4))*12+MONTH(B12)-MONTH(सारांश!$B$4)+IF(DAY(B12)>=DAY(सारांश!$B$4),1,0) -> 2 | E12: चरण 1: आधार निर्माण (प्रथम अध्ययन) | F12: 1857 का विद्रोह; सामाजिक-धार्मिक सुधार आंदोलन; प्रारंभिक राष्ट्रवाद: कांग्रेस, नरमपंथी, गरमपंथी, स्वदेशी | G12: बिहार – अर्थव्यवस्था, बजट एवं सरकारी योजनाएँ; बिहार – राजव्यवस्था एवं प्रशासन | H12: साप्ताहिक टेस्ट (100 MCQ, 90 मिनट) + विश्लेषण | I12: सूचीबद्ध सभी विषय पूरे करें; ~300 MCQ; साप्ताहिक टेस्ट ≥ 55% | J12: =COUNTIFS('दैनिक योजना'!$D$6:$D$552,A12,'दैनिक योजना'!$W$6:$W$552,"पूर्ण")+COUNTIFS('दैनिक योजना'!$D$6:$D$552,A12,'दैनिक योजना'!$W$6:$W$552,"दोहराया") -> 0 | K12: =IFERROR(J12/COUNTIF('दैनिक योजना'!$D$6:$D$552,A12),0) -> 0
A13: 7 | B13: =सारांश!$B$4+1+7*(A13-1) -> 46384 | C13: =B13+6 -> 46390 | D13: =(YEAR(B13)-YEAR(सारांश!$B$4))*12+MONTH(B13)-MONTH(सारांश!$B$4)+IF(DAY(B13)>=DAY(सारांश!$B$4),1,0) -> 2 | E13: चरण 1: आधार निर्माण (प्रथम अध्ययन) | F13: गांधी युग: चंपारण से भारत छोड़ो तक; क्रांतिकारी आंदोलन, संवैधानिक विकास एवं विभाजन | G13: बिहार – राजव्यवस्था एवं प्रशासन; बिहार – कला, संस्कृति, साहित्य एवं पर्यटन | H13: साप्ताहिक टेस्ट (100 MCQ, 90 मिनट) + विश्लेषण | I13: सूचीबद्ध सभी विषय पूरे करें; ~300 MCQ; साप्ताहिक टेस्ट ≥ 55% | J13: =COUNTIFS('दैनिक योजना'!$D$6:$D$552,A13,'दैनिक योजना'!$W$6:$W$552,"पूर्ण")+COUNTIFS('दैनिक योजना'!$D$6:$D$552,A13,'दैनिक योजना'!$W$6:$W$552,"दोहराया") -> 0 | K13: =IFERROR(J13/COUNTIF('दैनिक योजना'!$D$6:$D$552,A13),0) -> 0
A14: 8 | B14: =सारांश!$B$4+1+7*(A14-1) -> 46391 | C14: =B14+6 -> 46397 | D14: =(YEAR(B14)-YEAR(सारांश!$B$4))*12+MONTH(B14)-MONTH(सारांश!$B$4)+IF(DAY(B14)>=DAY(सारांश!$B$4),1,0) -> 2 | E14: चरण 1: आधार निर्माण (प्रथम अध्ययन) | F14: क्रांतिकारी आंदोलन, संवैधानिक विकास एवं विभाजन; स्वातंत्र्योत्तर भारत (1947 के बाद); भारतीय कला एवं स्थापत्य | G14: बिहार – कला, संस्कृति, साहित्य एवं पर्यटन; बिहार – जनसांख्यिकी, शिक्षा एवं स्वास्थ्य | H14: मासिक टेस्ट (150 प्रश्न, 2 घंटे, प्रारंभिक परीक्षा पैटर्न) + विश्लेषण + आधे दिन का विश्राम | I14: सूचीबद्ध सभी विषय पूरे करें; ~300 MCQ; साप्ताहिक टेस्ट ≥ 55% | J14: =COUNTIFS('दैनिक योजना'!$D$6:$D$552,A14,'दैनिक योजना'!$W$6:$W$552,"पूर्ण")+COUNTIFS('दैनिक योजना'!$D$6:$D$552,A14,'दैनिक योजना'!$W$6:$W$552,"दोहराया") -> 0 | K14: =IFERROR(J14/COUNTIF('दैनिक योजना'!$D$6:$D$552,A14),0) -> 0
A15: 9 | B15: =सारांश!$B$4+1+7*(A15-1) -> 46398 | C15: =B15+6 -> 46404 | D15: =(YEAR(B15)-YEAR(सारांश!$B$4))*12+MONTH(B15)-MONTH(सारांश!$B$4)+IF(DAY(B15)>=DAY(सारांश!$B$4),1,0) -> 2 | E15: चरण 1: आधार निर्माण (प्रथम अध्ययन) | F15: प्रदर्शन कलाएँ, साहित्य, त्योहार एवं यूनेस्को स्थल; ब्रह्मांड, सौरमंडल एवं पृथ्वी | G15: बिहार – जनसांख्यिकी, शिक्षा एवं स्वास्थ्य; भौतिकी I: गति, बल, कार्य एवं गुरुत्वाकर्षण | H15: साप्ताहिक टेस्ट (100 MCQ, 90 मिनट) + विश्लेषण | I15: सूचीबद्ध सभी विषय पूरे करें; ~300 MCQ; साप्ताहिक टेस्ट ≥ 55% | J15: =COUNTIFS('दैनिक योजना'!$D$6:$D$552,A15,'दैनिक योजना'!$W$6:$W$552,"पूर्ण")+COUNTIFS('दैनिक योजना'!$D$6:$D$552,A15,'दैनिक योजना'!$W$6:$W$552,"दोहराया") -> 0 | K15: =IFERROR(J15/COUNTIF('दैनिक योजना'!$D$6:$D$552,A15),0) -> 0
A16: 10 | B16: =सारांश!$B$4+1+7*(A16-1) -> 46405 | C16: =B16+6 -> 46411 | D16: =(YEAR(B16)-YEAR(सारांश!$B$4))*12+MONTH(B16)-MONTH(सारांश!$B$4)+IF(DAY(B16)>=DAY(सारांश!$B$4),1,0) -> 3 | E16: चरण 1: आधार निर्माण (प्रथम अध्ययन) | F16: ब्रह्मांड, सौरमंडल एवं पृथ्वी; भू-आकृति विज्ञान: पृथ्वी का आंतरिक भाग, चट्टानें एवं स्थलरूप; जलवायु विज्ञान: वायुमंडल, पवनें एवं जलवायु | G16: भौतिकी I: गति, बल, कार्य एवं गुरुत्वाकर्षण; भौतिकी II: ऊष्मा, प्रकाश, ध्वनि, विद्युत एवं आधुनिक भौतिकी | H16: साप्ताहिक टेस्ट (100 MCQ, 90 मिनट) + विश्लेषण | I16: सूचीबद्ध सभी विषय पूरे करें; ~300 MCQ; साप्ताहिक टेस्ट ≥ 55% | J16: =COUNTIFS('दैनिक योजना'!$D$6:$D$552,A16,'दैनिक योजना'!$W$6:$W$552,"पूर्ण")+COUNTIFS('दैनिक योजना'!$D$6:$D$552,A16,'दैनिक योजना'!$W$6:$W$552,"दोहराया") -> 0 | K16: =IFERROR(J16/COUNTIF('दैनिक योजना'!$D$6:$D$552,A16),0) -> 0
A17: 11 | B17: =सारांश!$B$4+1+7*(A17-1) -> 46412 | C17: =B17+6 -> 46418 | D17: =(YEAR(B17)-YEAR(सारांश!$B$4))*12+MONTH(B17)-MONTH(सारांश!$B$4)+IF(DAY(B17)>=DAY(सारांश!$B$4),1,0) -> 3 | E17: चरण 1: आधार निर्माण (प्रथम अध्ययन) | F17: जलवायु विज्ञान: वायुमंडल, पवनें एवं जलवायु; समुद्र विज्ञान; भारत का भौतिक स्वरूप | G17: भौतिकी II: ऊष्मा, प्रकाश, ध्वनि, विद्युत एवं आधुनिक भौतिकी; रसायन I: पदार्थ, परमाणु, आवर्त सारणी एवं अम्ल-क्षार | H17: साप्ताहिक टेस्ट (100 MCQ, 90 मिनट) + विश्लेषण | I17: सूचीबद्ध सभी विषय पूरे करें; ~300 MCQ; साप्ताहिक टेस्ट ≥ 55% | J17: =COUNTIFS('दैनिक योजना'!$D$6:$D$552,A17,'दैनिक योजना'!$W$6:$W$552,"पूर्ण")+COUNTIFS('दैनिक योजना'!$D$6:$D$552,A17,'दैनिक योजना'!$W$6:$W$552,"दोहराया") -> 0 | K17: =IFERROR(J17/COUNTIF('दैनिक योजना'!$D$6:$D$552,A17),0) -> 0
A18: 12 | B18: =सारांश!$B$4+1+7*(A18-1) -> 46419 | C18: =B18+6 -> 46425 | D18: =(YEAR(B18)-YEAR(सारांश!$B$4))*12+MONTH(B18)-MONTH(सारांश!$B$4)+IF(DAY(B18)>=DAY(सारांश!$B$4),1,0) -> 3 | E18: चरण 1: आधार निर्माण (प्रथम अध्ययन) | F18: भारत का भौतिक स्वरूप; भारतीय अपवाह तंत्र; भारत की जलवायु, मानसून, मृदा एवं वनस्पति | G18: रसायन I: पदार्थ, परमाणु, आवर्त सारणी एवं अम्ल-क्षार; रसायन II: धातु, कार्बन यौगिक एवं दैनिक जीवन में रसायन | H18: मासिक टेस्ट (150 प्रश्न, 2 घंटे, प्रारंभिक परीक्षा पैटर्न) + विश्लेषण + आधे दिन का विश्राम | I18: सूचीबद्ध सभी विषय पूरे करें; ~300 MCQ; साप्ताहिक टेस्ट ≥ 55% | J18: =COUNTIFS('दैनिक योजना'!$D$6:$D$552,A18,'दैनिक योजना'!$W$6:$W$552,"पूर्ण")+COUNTIFS('दैनिक योजना'!$D$6:$D$552,A18,'दैनिक योजना'!$W$6:$W$552,"दोहराया") -> 0 | K18: =IFERROR(J18/COUNTIF('दैनिक योजना'!$D$6:$D$552,A18),0) -> 0
... A84: 78 | B84: =सारांश!$B$4+1+7*(A84-1) -> 46881 | C84: =B84+6 -> 46887 | D84: =(YEAR(B84)-YEAR(सारांश!$B$4))*12+MONTH(B84)-MONTH(सारांश!$B$4)+IF(DAY(B84)>=DAY(सारांश!$B$4),1,0) -> 18 | E84: चरण 3C: अंतिम मॉक एवं पुनरावृत्ति | F84: अंतिम पुनरावृत्ति | G84: अंतिम पुनरावृत्ति | H84: अंतिम विश्राम दिवस: संक्षिप्त नोट्स पर नज़र, परीक्षा-दिवस की तैयारी, जल्दी सोएँ | I84: सूचीबद्ध सभी विषय पूरे करें; ~300 MCQ; साप्ताहिक टेस्ट ≥ 85% | J84: =COUNTIFS('दैनिक योजना'!$D$6:$D$552,A84,'दैनिक योजना'!$W$6:$W$552,"पूर्ण")+COUNTIFS('दैनिक योजना'!$D$6:$D$552,A84,'दैनिक योजना'!$W$6:$W$552,"दोहराया") -> 0 | K84: =IFERROR(J84/COUNTIF('दैनिक योजना'!$D$6:$D$552,A84),0) -> 0

Sheet दैनिक योजना
A1: दैनिक योजना – BPSC 1.5 वर्षीय अध्ययन कार्यक्रम
A2: सोम–शनि: 7.5 घंटे (प्राथमिक 3 • द्वितीयक 2 • करेंट अफेयर्स 1 • अभ्यास 1 • पुनरावृत्ति 0.5)। रविवार: टेस्ट + पुनरावृत्ति। प्रगति के लिए 'स्थिति' (कॉलम W) बदलें।
A5: दिन # | B5: दिनांक | C5: वार | D5: सप्ताह # | E5: माह # | F5: चरण | G5: प्राथमिक विषय-क्षेत्र | H5: प्राथमिक विषय (3 घंटे) | I5: पढ़ने योग्य मुख्य सैद्धांतिक बिंदु (अध्ययन रूपरेखा) | J5: सैद्धांतिक अध्ययन एवं PDF नोट्स | K5: सैद्धांतिक अध्ययन – वेबसाइट लिंक | L5: द्वितीयक विषय-क्षेत्र | M5: द्वितीयक विषय (2 घंटे) | N5: करेंट अफेयर्स (1 घंटा) | O5: अभ्यास (1 घंटा) | P5: पुनरावृत्ति (0.5 घंटा) | Q5: अध्ययन घंटे | R5: नोट्स / पुस्तकें – प्राथमिक | S5: नोट्स / पुस्तकें – द्वितीयक | T5: YouTube – प्राथमिक (दृष्टि IAS) | U5: YouTube – प्राथमिक (BPSC वाला) | V5: YouTube – द्वितीयक (BPSC वाला) | W5: स्थिति | X5: टिप्पणी | Y5: सैद्धांतिक अध्ययन – थ्योरी वेबसाइट लिंक (आज का प्राथमिक विषय)
A6: 1 | B6: =सारांश!$B$4+A6-1 -> 46341 | C6: =CHOOSE(WEEKDAY(B6,2),"सोमवार","मंगलवार","बुधवार","गुरुवार","शुक्रवार","शनिवार","रविवार") -> रविवार | D6: =IF(A6=1,0,INT((A6-2)/7)+1) -> 0 | E6: =(YEAR(B6)-YEAR(सारांश!$B$4))*12+MONTH(B6)-MONTH(सारांश!$B$4)+IF(DAY(B6)>=DAY(सारांश!$B$4),1,0) -> 1 | F6: शुभारंभ दिवस | G6: प्रारंभिक दिशा-निर्देश | H6: शुभारंभ: पाठ्यक्रम, PYQ विश्लेषण एवं डायग्नोस्टिक टेस्ट | I6: BPSC पाठ्यक्रम व पिछले 5 वर्षों के PYQ डाउनलोड करें; NCERT/पुस्तकें जुटाएँ; नोट्स प्रणाली (डिजिटल/कागज़) बनाएँ; 100 प्रश्नों का डायग्नोस्टिक टेस्ट दें; कमज़ोर विषय चिह्नित करें | J6: केवल अपने संक्षिप्त नोट्स के PDF और त्रुटि-लॉग पढ़ें। आज के मॉक का विश्लेषण PDF पृष्ठ के रूप में सहेजें (गलत प्रश्न + सही अवधारणा)। | K6: वेबसाइट पर पढ़ें: bpsc.bihar.gov.in • drishtiias.com • visionias.in (क्लिक करें) | L6: योजना | M6: ट्रैकर, दैनिक समय-सारणी व नींद-पढ़ाई की दिनचर्या तय करें | N6: दैनिक समाचार पत्र + दृष्टि IAS करेंट अफेयर्स शुरू करें | O6: डायग्नोस्टिक टेस्ट (100 MCQ, 90 मिनट) + विश्लेषण | P6: — | Q6: 6 | R6: NCERT • मानक पुस्तकें | S6: स्वयं के संक्षिप्त नोट्स • त्रुटि-लॉग • साप्ताहिक करेंट अफेयर्स (दृष्टि / विजन IAS) | T6: ▶ दृष्टि IAS | U6: ▶ BPSC वाला | V6: ▶ BPSC वाला | W6: शुरू नहीं हुआ
A7: 2 | B7: =सारांश!$B$4+A7-1 -> 46342 | C7: =CHOOSE(WEEKDAY(B7,2),"सोमवार","मंगलवार","बुधवार","गुरुवार","शुक्रवार","शनिवार","रविवार") -> सोमवार | D7: =IF(A7=1,0,INT((A7-2)/7)+1) -> 1 | E7: =(YEAR(B7)-YEAR(सारांश!$B$4))*12+MONTH(B7)-MONTH(सारांश!$B$4)+IF(DAY(B7)>=DAY(सारांश!$B$4),1,0) -> 1 | F7: चरण 1: आधार निर्माण (प्रथम अध्ययन) | G7: इतिहास | H7: प्रागैतिहास एवं सिंधु घाटी सभ्यता (भाग 1/3) | I7: पाषाण–ताम्र युग; सिंधु सभ्यता के स्थल (हड़प्पा, मोहनजोदड़ो, लोथल, धौलावीरा, कालीबंगा); नगर नियोजन, व्यापार, धर्म, लिपि; पतन के कारण | J7: पढ़ें: प्रागैतिहास एवं सिंधु घाटी सभ्यता – NCERT इतिहास (कक्षा 6-12) • स्पेक्ट्रम आधुनिक भारत • दृष्टि IAS इतिहास नोट्स (हिंदी)। फिर स्वयं के 1-2 पृष्ठ के नोट्स + 10 फ्लैश-कार्ड बनाएँ और PDF के रूप में सहेजें ('प्रागैतिहास एवं सिंधु घाटी.pdf')। तैयार PDF नोट्स खोजने हेतु क्लिक करें। | K7: वेबसाइट पर पढ़ें: drishtiias.com • visionias.in • ncert.nic.in (क्लिक करें) | L7: बिहार विशेष | M7: बिहार – प्राचीन इतिहास (भाग 1/5) | N7: बिहार समाचार (प्रभात खबर / दैनिक जागरण) + दृष्टि IAS दैनिक करेंट अफेयर्स | O7: आज के विषय पर 50 MCQ (+ उससे संबंधित BPSC PYQ) | P7: कल के नोट्स दोहराएँ (30 मिनट) | Q7: 7.5 | R7: NCERT इतिहास (कक्षा 6-12) • स्पेक्ट्रम आधुनिक भारत • दृष्टि IAS इतिहास नोट्स (हिंदी) • विजन IAS PT365/क्लास नोट्स • BPSC वाला क्लास नोट्स | S7: नवीनतम बिहार आर्थिक सर्वेक्षण व बजट • BPSC वाला बिहार विशेष • दृष्टि IAS बिहार विशेष (हिंदी) • राज्य सरकार के पोर्टल • बिहार सामान्य ज्ञान पुस्तक (लूसेंट/प्रभात) | T7: ▶ दृष्टि IAS | U7: ▶ BPSC वाला | V7: ▶ BPSC वाला | W7: शुरू नहीं हुआ | Y7: 📖 पढ़ें: दृष्टि • विजन • NCERT • जागरण जोश • GKToday
A8: 3 | B8: =सारांश!$B$4+A8-1 -> 46343 | C8: =CHOOSE(WEEKDAY(B8,2),"सोमवार","मंगलवार","बुधवार","गुरुवार","शुक्रवार","शनिवार","रविवार") -> मंगलवार | D8: =IF(A8=1,0,INT((A8-2)/7)+1) -> 1 | E8: =(YEAR(B8)-YEAR(सारांश!$B$4))*12+MONTH(B8)-MONTH(सारांश!$B$4)+IF(DAY(B8)>=DAY(सारांश!$B$4),1,0) -> 1 | F8: चरण 1: आधार निर्माण (प्रथम अध्ययन) | G8: इतिहास | H8: प्रागैतिहास एवं सिंधु घाटी सभ्यता (भाग 2/3) | I8: पाषाण–ताम्र युग; सिंधु सभ्यता के स्थल (हड़प्पा, मोहनजोदड़ो, लोथल, धौलावीरा, कालीबंगा); नगर नियोजन, व्यापार, धर्म, लिपि; पतन के कारण | J8: पढ़ें: प्रागैतिहास एवं सिंधु घाटी सभ्यता – NCERT इतिहास (कक्षा 6-12) • स्पेक्ट्रम आधुनिक भारत • दृष्टि IAS इतिहास नोट्स (हिंदी)। फिर स्वयं के 1-2 पृष्ठ के नोट्स + 10 फ्लैश-कार्ड बनाएँ और PDF के रूप में सहेजें ('प्रागैतिहास एवं सिंधु घाटी.pdf')। तैयार PDF नोट्स खोजने हेतु क्लिक करें। | K8: वेबसाइट पर पढ़ें: drishtiias.com • visionias.in • ncert.nic.in (क्लिक करें) | L8: बिहार विशेष | M8: बिहार – प्राचीन इतिहास (भाग 2/5) | N8: राजव्यवस्था, शासन व अर्थव्यवस्था के समाचार (द हिंदू / दृष्टि IAS) | O8: आज के विषय पर 50 MCQ (+ उससे संबंधित BPSC PYQ) | P8: कल के नोट्स दोहराएँ (30 मिनट) | Q8: 7.5 | R8: NCERT इतिहास (कक्षा 6-12) • स्पेक्ट्रम आधुनिक भारत • दृष्टि IAS इतिहास नोट्स (हिंदी) • विजन IAS PT365/क्लास नोट्स • BPSC वाला क्लास नोट्स | S8: नवीनतम बिहार आर्थिक सर्वेक्षण व बजट • BPSC वाला बिहार विशेष • दृष्टि IAS बिहार विशेष (हिंदी) • राज्य सरकार के पोर्टल • बिहार सामान्य ज्ञान पुस्तक (लूसेंट/प्रभात) | T8: ▶ दृष्टि IAS | U8: ▶ BPSC वाला | V8: ▶ BPSC वाला | W8: शुरू नहीं हुआ | Y8: 📖 पढ़ें: दृष्टि • विजन • NCERT • जागरण जोश • GKToday
A9: 4 | B9: =सारांश!$B$4+A9-1 -> 46344 | C9: =CHOOSE(WEEKDAY(B9,2),"सोमवार","मंगलवार","बुधवार","गुरुवार","शुक्रवार","शनिवार","रविवार") -> बुधवार | D9: =IF(A9=1,0,INT((A9-2)/7)+1) -> 1 | E9: =(YEAR(B9)-YEAR(सारांश!$B$4))*12+MONTH(B9)-MONTH(सारांश!$B$4)+IF(DAY(B9)>=DAY(सारांश!$B$4),1,0) -> 1 | F9: चरण 1: आधार निर्माण (प्रथम अध्ययन) | G9: इतिहास | H9: प्रागैतिहास एवं सिंधु घाटी सभ्यता (भाग 3/3) | I9: पाषाण–ताम्र युग; सिंधु सभ्यता के स्थल (हड़प्पा, मोहनजोदड़ो, लोथल, धौलावीरा, कालीबंगा); नगर नियोजन, व्यापार, धर्म, लिपि; पतन के कारण | J9: पढ़ें: प्रागैतिहास एवं सिंधु घाटी सभ्यता – NCERT इतिहास (कक्षा 6-12) • स्पेक्ट्रम आधुनिक भारत • दृष्टि IAS इतिहास नोट्स (हिंदी)। फिर स्वयं के 1-2 पृष्ठ के नोट्स + 10 फ्लैश-कार्ड बनाएँ और PDF के रूप में सहेजें ('प्रागैतिहास एवं सिंधु घाटी.pdf')। तैयार PDF नोट्स खोजने हेतु क्लिक करें। | K9: वेबसाइट पर पढ़ें: drishtiias.com • visionias.in • ncert.nic.in (क्लिक करें) | L9: बिहार विशेष | M9: बिहार – प्राचीन इतिहास (भाग 3/5) | N9: विज्ञान-प्रौद्योगिकी, अंतरिक्ष व रक्षा समाचार | O9: आज के विषय पर 50 MCQ (+ उससे संबंधित BPSC PYQ) | P9: कल के नोट्स दोहराएँ (30 मिनट) | Q9: 7.5 | R9: NCERT इतिहास (कक्षा 6-12) • स्पेक्ट्रम आधुनिक भारत • दृष्टि IAS इतिहास नोट्स (हिंदी) • विजन IAS PT365/क्लास नोट्स • BPSC वाला क्लास नोट्स | S9: नवीनतम बिहार आर्थिक सर्वेक्षण व बजट • BPSC वाला बिहार विशेष • दृष्टि IAS बिहार विशेष (हिंदी) • राज्य सरकार के पोर्टल • बिहार सामान्य ज्ञान पुस्तक (लूसेंट/प्रभात) | T9: ▶ दृष्टि IAS | U9: ▶ BPSC वाला | V9: ▶ BPSC वाला | W9: शुरू नहीं हुआ | Y9: 📖 पढ़ें: दृष्टि • विजन • NCERT • जागरण जोश • GKToday
A10: 5 | B10: =सारांश!$B$4+A10-1 -> 46345 | C10: =CHOOSE(WEEKDAY(B10,2),"सोमवार","मंगलवार","बुधवार","गुरुवार","शुक्रवार","शनिवार","रविवार") -> गुरुवार | D10: =IF(A10=1,0,INT((A10-2)/7)+1) -> 1 | E10: =(YEAR(B10)-YEAR(सारांश!$B$4))*12+MONTH(B10)-MONTH(सारांश!$B$4)+IF(DAY(B10)>=DAY(सारांश!$B$4),1,0) -> 1 | F10: चरण 1: आधार निर्माण (प्रथम अध्ययन) | G10: इतिहास | H10: वैदिक काल एवं महाजनपद (भाग 1/3) | I10: पूर्व एवं उत्तर वैदिक समाज, राजनीति, अर्थव्यवस्था, धर्म; 16 महाजनपद; मगध का उत्कर्ष (बिम्बिसार, अजातशत्रु, नंद); लौह युग; द्वितीय नगरीकरण | J10: पढ़ें: वैदिक काल एवं महाजनपद – NCERT इतिहास (कक्षा 6-12) • स्पेक्ट्रम आधुनिक भारत • दृष्टि IAS इतिहास नोट्स (हिंदी)। फिर स्वयं के 1-2 पृष्ठ के नोट्स + 10 फ्लैश-कार्ड बनाएँ और PDF के रूप में सहेजें ('वैदिक काल एवं महाजनपद.pdf')। तैयार PDF नोट्स खोजने हेतु क्लिक करें। | K10: वेबसाइट पर पढ़ें: drishtiias.com • visionias.in • ncert.nic.in (क्लिक करें) | L10: बिहार विशेष | M10: बिहार – प्राचीन इतिहास (भाग 4/5) | N10: अंतर्राष्ट्रीय संबंध, शिखर सम्मेलन व भारत के पड़ोसी | O10: आज के विषय पर 50 MCQ (+ उससे संबंधित BPSC PYQ) | P10: कल के नोट्स दोहराएँ (30 मिनट) | Q10: 7.5 | R10: NCERT इतिहास (कक्षा 6-12) • स्पेक्ट्रम आधुनिक भारत • दृष्टि IAS इतिहास नोट्स (हिंदी) • विजन IAS PT365/क्लास नोट्स • BPSC वाला क्लास नोट्स | S10: नवीनतम बिहार आर्थिक सर्वेक्षण व बजट • BPSC वाला बिहार विशेष • दृष्टि IAS बिहार विशेष (हिंदी) • राज्य सरकार के पोर्टल • बिहार सामान्य ज्ञान पुस्तक (लूसेंट/प्रभात) | T10: ▶ दृष्टि IAS | U10: ▶ BPSC वाला | V10: ▶ BPSC वाला | W10: शुरू नहीं हुआ | Y10: 📖 पढ़ें: दृष्टि • विजन • NCERT • जागरण जोश • GKToday
A11: 6 | B11: =सारांश!$B$4+A11-1 -> 46346 | C11: =CHOOSE(WEEKDAY(B11,2),"सोमवार","मंगलवार","बुधवार","गुरुवार","शुक्रवार","शनिवार","रविवार") -> शुक्रवार | D11: =IF(A11=1,0,INT((A11-2)/7)+1) -> 1 | E11: =(YEAR(B11)-YEAR(सारांश!$B$4))*12+MONTH(B11)-MONTH(सारांश!$B$4)+IF(DAY(B11)>=DAY(सारांश!$B$4),1,0) -> 1 | F11: चरण 1: आधार निर्माण (प्रथम अध्ययन) | G11: इतिहास | H11: वैदिक काल एवं महाजनपद (भाग 2/3) | I11: पूर्व एवं उत्तर वैदिक समाज, राजनीति, अर्थव्यवस्था, धर्म; 16 महाजनपद; मगध का उत्कर्ष (बिम्बिसार, अजातशत्रु, नंद); लौह युग; द्वितीय नगरीकरण | J11: पढ़ें: वैदिक काल एवं महाजनपद – NCERT इतिहास (कक्षा 6-12) • स्पेक्ट्रम आधुनिक भारत • दृष्टि IAS इतिहास नोट्स (हिंदी)। फिर स्वयं के 1-2 पृष्ठ के नोट्स + 10 फ्लैश-कार्ड बनाएँ और PDF के रूप में सहेजें ('वैदिक काल एवं महाजनपद.pdf')। तैयार PDF नोट्स खोजने हेतु क्लिक करें। | K11: वेबसाइट पर पढ़ें: drishtiias.com • visionias.in • ncert.nic.in (क्लिक करें) | L11: बिहार विशेष | M11: बिहार – प्राचीन इतिहास (भाग 5/5) | N11: पर्यावरण, योजनाएँ, रिपोर्ट व सूचकांक | O11: आज के विषय पर 50 MCQ (+ उससे संबंधित BPSC PYQ) | P11: कल के नोट्स दोहराएँ (30 मिनट) | Q11: 7.5 | R11: NCERT इतिहास (कक्षा 6-12) • स्पेक्ट्रम आधुनिक भारत • दृष्टि IAS इतिहास नोट्स (हिंदी) • विजन IAS PT365/क्लास नोट्स • BPSC वाला क्लास नोट्स | S11: नवीनतम बिहार आर्थिक सर्वेक्षण व बजट • BPSC वाला बिहार विशेष • दृष्टि IAS बिहार विशेष (हिंदी) • राज्य सरकार के पोर्टल • बिहार सामान्य ज्ञान पुस्तक (लूसेंट/प्रभात) | T11: ▶ दृष्टि IAS | U11: ▶ BPSC वाला | V11: ▶ BPSC वाला | W11: शुरू नहीं हुआ | Y11: 📖 पढ़ें: दृष्टि • विजन • NCERT • जागरण जोश • GKToday
A12: 7 | B12: =सारांश!$B$4+A12-1 -> 46347 | C12: =CHOOSE(WEEKDAY(B12,2),"सोमवार","मंगलवार","बुधवार","गुरुवार","शुक्रवार","शनिवार","रविवार") -> शनिवार | D12: =IF(A12=1,0,INT((A12-2)/7)+1) -> 1 | E12: =(YEAR(B12)-YEAR(सारांश!$B$4))*12+MONTH(B12)-MONTH(सारांश!$B$4)+IF(DAY(B12)>=DAY(सारांश!$B$4),1,0) -> 1 | F12: चरण 1: आधार निर्माण (प्रथम अध्ययन) | G12: इतिहास | H12: वैदिक काल एवं महाजनपद (भाग 3/3) | I12: पूर्व एवं उत्तर वैदिक समाज, राजनीति, अर्थव्यवस्था, धर्म; 16 महाजनपद; मगध का उत्कर्ष (बिम्बिसार, अजातशत्रु, नंद); लौह युग; द्वितीय नगरीकरण | J12: पढ़ें: वैदिक काल एवं महाजनपद – NCERT इतिहास (कक्षा 6-12) • स्पेक्ट्रम आधुनिक भारत • दृष्टि IAS इतिहास नोट्स (हिंदी)। फिर स्वयं के 1-2 पृष्ठ के नोट्स + 10 फ्लैश-कार्ड बनाएँ और PDF के रूप में सहेजें ('वैदिक काल एवं महाजनपद.pdf')। तैयार PDF नोट्स खोजने हेतु क्लिक करें। | K12: वेबसाइट पर पढ़ें: drishtiias.com • visionias.in • ncert.nic.in (क्लिक करें) | L12: बिहार विशेष | M12: बिहार – मध्यकालीन एवं औपनिवेशिक इतिहास (भाग 1/5) | N12: साप्ताहिक करेंट अफेयर्स संकलन + 20 MCQ (दृष्टि / विजन IAS साप्ताहिक) | O12: आज के विषय पर 50 MCQ (+ उससे संबंधित BPSC PYQ) | P12: कल के नोट्स दोहराएँ (30 मिनट) | Q12: 7.5 | R12: NCERT इतिहास (कक्षा 6-12) • स्पेक्ट्रम आधुनिक भारत • दृष्टि IAS इतिहास नोट्स (हिंदी) • विजन IAS PT365/क्लास नोट्स • BPSC वाला क्लास नोट्स | S12: नवीनतम बिहार आर्थिक सर्वेक्षण व बजट • BPSC वाला बिहार विशेष • दृष्टि IAS बिहार विशेष (हिंदी) • राज्य सरकार के पोर्टल • बिहार सामान्य ज्ञान पुस्तक (लूसेंट/प्रभात) | T12: ▶ दृष्टि IAS | U12: ▶ BPSC वाला | V12: ▶ BPSC वाला | W12: शुरू नहीं हुआ | Y12: 📖 पढ़ें: दृष्टि • विजन • NCERT • जागरण जोश • GKToday
A13: 8 | B13: =सारांश!$B$4+A13-1 -> 46348 | C13: =CHOOSE(WEEKDAY(B13,2),"सोमवार","मंगलवार","बुधवार","गुरुवार","शुक्रवार","शनिवार","रविवार") -> रविवार | D13: =IF(A13=1,0,INT((A13-2)/7)+1) -> 1 | E13: =(YEAR(B13)-YEAR(सारांश!$B$4))*12+MONTH(B13)-MONTH(सारांश!$B$4)+IF(DAY(B13)>=DAY(सारांश!$B$4),1,0) -> 1 | F13: चरण 1: आधार निर्माण (प्रथम अध्ययन) | G13: टेस्ट एवं पुनरावृत्ति | H13: साप्ताहिक टेस्ट (100 MCQ, 90 मिनट) + विश्लेषण | I13: इस सप्ताह के विषय दोहराएँ: प्रागैतिहास एवं सिंधु घाटी सभ्यता; वैदिक काल एवं महाजनपद। त्रुटि-लॉग अद्यतन करें; 20 कमज़ोर बिंदु सूचीबद्ध करें; संक्षिप्त नोट्स दोबारा पढ़ें। | J13: इस सप्ताह के अपने PDF/हस्तलिखित नोट्स दोबारा पढ़ें। उन्हें 1 पृष्ठ के साप्ताहिक सारांश PDF में जोड़ें (त्रुटि-लॉग + 20 कमज़ोर बिंदु)। | K13: वेबसाइट पर पढ़ें: drishtiias.com • visionias.in • pib.gov.in (क्लिक करें) | L13: पुनरावृत्ति | M13: सप्ताह के द्वितीयक/बिहार विषय दोहराएँ + साप्ताहिक करेंट अफेयर्स संकलन | N13: साप्ताहिक करेंट अफेयर्स संकलन (दृष्टि IAS / विजन IAS साप्ताहिक) + 20 MCQ | O13: लक्ष्य अंक: 55%+ (साप्ताहिक शीट में अपना स्कोर दर्ज करें) | P13: पूरे सप्ताह की पुनरावृत्ति (2 घंटे) | Q13: 6 | R13: BPSC वाला / दृष्टि IAS / विजन IAS टेस्ट सीरीज़ • BPSC के PYQ (bpsc.bihar.gov.in) | S13: स्वयं के संक्षिप्त नोट्स • त्रुटि-लॉग • साप्ताहिक करेंट अफेयर्स (दृष्टि / विजन IAS) | T13: ▶ दृष्टि IAS | U13: ▶ BPSC वाला | V13: ▶ BPSC वाला | W13: शुरू नहीं हुआ
A14: 9 | B14: =सारांश!$B$4+A14-1 -> 46349 | C14: =CHOOSE(WEEKDAY(B14,2),"सोमवार","मंगलवार","बुधवार","गुरुवार","शुक्रवार","शनिवार","रविवार") -> सोमवार | D14: =IF(A14=1,0,INT((A14-2)/7)+1) -> 2 | E14: =(YEAR(B14)-YEAR(सारांश!$B$4))*12+MONTH(B14)-MONTH(सारांश!$B$4)+IF(DAY(B14)>=DAY(सारांश!$B$4),1,0) -> 1 | F14: चरण 1: आधार निर्माण (प्रथम अध्ययन) | G14: इतिहास | H14: जैन, बौद्ध एवं अन्य नास्तिक संप्रदाय (भाग 1/2) | I14: महावीर एवं बुद्ध का जीवन व शिक्षाएँ; चार आर्य सत्य, अष्टांगिक मार्ग; बौद्ध संगीतियाँ (राजगृह, वैशाली, पाटलिपुत्र); संप्रदाय; बिहार से संबंध (बोधगया, राजगीर, वैशाली) | J14: पढ़ें: जैन, बौद्ध एवं अन्य नास्तिक संप्रदाय – NCERT इतिहास (कक्षा 6-12) • स्पेक्ट्रम आधुनिक भारत • दृष्टि IAS इतिहास नोट्स (हिंदी)। फिर स्वयं के 1-2 पृष्ठ के नोट्स + 10 फ्लैश-कार्ड बनाएँ और PDF के रूप में सहेजें ('जैन, बौद्ध एवं अन्य नास्तिक.pdf')। तैयार PDF नोट्स खोजने हेतु क्लिक करें। | K14: वेबसाइट पर पढ़ें: drishtiias.com • visionias.in • ncert.nic.in (क्लिक करें) | L14: बिहार विशेष | M14: बिहार – मध्यकालीन एवं औपनिवेशिक इतिहास (भाग 2/5) | N14: बिहार समाचार (प्रभात खबर / दैनिक जागरण) + दृष्टि IAS दैनिक करेंट अफेयर्स | O14: आज के विषय पर 50 MCQ (+ उससे संबंधित BPSC PYQ) | P14: कल के नोट्स दोहराएँ (30 मिनट) | Q14: 7.5 | R14: NCERT इतिहास (कक्षा 6-12) • स्पेक्ट्रम आधुनिक भारत • दृष्टि IAS इतिहास नोट्स (हिंदी) • विजन IAS PT365/क्लास नोट्स • BPSC वाला क्लास नोट्स | S14: नवीनतम बिहार आर्थिक सर्वेक्षण व बजट • BPSC वाला बिहार विशेष • दृष्टि IAS बिहार विशेष (हिंदी) • राज्य सरकार के पोर्टल • बिहार सामान्य ज्ञान पुस्तक (लूसेंट/प्रभात) | T14: ▶ दृष्टि IAS | U14: ▶ BPSC वाला | V14: ▶ BPSC वाला | W14: शुरू नहीं हुआ | Y14: 📖 पढ़ें: दृष्टि • विजन • NCERT • जागरण जोश • GKToday
A15: 10 | B15: =सारांश!$B$4+A15-1 -> 46350 | C15: =CHOOSE(WEEKDAY(B15,2),"सोमवार","मंगलवार","बुधवार","गुरुवार","शुक्रवार","शनिवार","रविवार") -> मंगलवार | D15: =IF(A15=1,0,INT((A15-2)/7)+1) -> 2 | E15: =(YEAR(B15)-YEAR(सारांश!$B$4))*12+MONTH(B15)-MONTH(सारांश!$B$4)+IF(DAY(B15)>=DAY(सारांश!$B$4),1,0) -> 1 | F15: चरण 1: आधार निर्माण (प्रथम अध्ययन) | G15: इतिहास | H15: जैन, बौद्ध एवं अन्य नास्तिक संप्रदाय (भाग 2/2) | I15: महावीर एवं बुद्ध का जीवन व शिक्षाएँ; चार आर्य सत्य, अष्टांगिक मार्ग; बौद्ध संगीतियाँ (राजगृह, वैशाली, पाटलिपुत्र); संप्रदाय; बिहार से संबंध (बोधगया, राजगीर, वैशाली) | J15: पढ़ें: जैन, बौद्ध एवं अन्य नास्तिक संप्रदाय – NCERT इतिहास (कक्षा 6-12) • स्पेक्ट्रम आधुनिक भारत • दृष्टि IAS इतिहास नोट्स (हिंदी)। फिर स्वयं के 1-2 पृष्ठ के नोट्स + 10 फ्लैश-कार्ड बनाएँ और PDF के रूप में सहेजें ('जैन, बौद्ध एवं अन्य नास्तिक.pdf')। तैयार PDF नोट्स खोजने हेतु क्लिक करें। | K15: वेबसाइट पर पढ़ें: drishtiias.com • visionias.in • ncert.nic.in (क्लिक करें) | L15: बिहार विशेष | M15: बिहार – मध्यकालीन एवं औपनिवेशिक इतिहास (भाग 3/5) | N15: राजव्यवस्था, शासन व अर्थव्यवस्था के समाचार (द हिंदू / दृष्टि IAS) | O15: आज के विषय पर 50 MCQ (+ उससे संबंधित BPSC PYQ) | P15: कल के नोट्स दोहराएँ (30 मिनट) | Q15: 7.5 | R15: NCERT इतिहास (कक्षा 6-12) • स्पेक्ट्रम आधुनिक भारत • दृष्टि IAS इतिहास नोट्स (हिंदी) • विजन IAS PT365/क्लास नोट्स • BPSC वाला क्लास नोट्स | S15: नवीनतम बिहार आर्थिक सर्वेक्षण व बजट • BPSC वाला बिहार विशेष • दृष्टि IAS बिहार विशेष (हिंदी) • राज्य सरकार के पोर्टल • बिहार सामान्य ज्ञान पुस्तक (लूसेंट/प्रभात) | T15: ▶ दृष्टि IAS | U15: ▶ BPSC वाला | V15: ▶ BPSC वाला | W15: शुरू नहीं हुआ | Y15: 📖 पढ़ें: दृष्टि • विजन • NCERT • जागरण जोश • GKToday
A16: 11 | B16: =सारांश!$B$4+A16-1 -> 46351 | C16: =CHOOSE(WEEKDAY(B16,2),"सोमवार","मंगलवार","बुधवार","गुरुवार","शुक्रवार","शनिवार","रविवार") -> बुधवार | D16: =IF(A16=1,0,INT((A16-2)/7)+1) -> 2 | E16: =(YEAR(B16)-YEAR(सारांश!$B$4))*12+MONTH(B16)-MONTH(सारांश!$B$4)+IF(DAY(B16)>=DAY(सारांश!$B$4),1,0) -> 1 | F16: चरण 1: आधार निर्माण (प्रथम अध्ययन) | G16: इतिहास | H16: मौर्य साम्राज्य (भाग 1/3) | I16: चंद्रगुप्त, बिंदुसार, अशोक; कलिंग युद्ध व धम्म; अभिलेख; अर्थशास्त्र; मेगस्थनीज; प्रशासन, अर्थव्यवस्था, कला; पतन | J16: पढ़ें: मौर्य साम्राज्य – NCERT इतिहास (कक्षा 6-12) • स्पेक्ट्रम आधुनिक भारत • दृष्टि IAS इतिहास नोट्स (हिंदी)। फिर स्वयं के 1-2 पृष्ठ के नोट्स + 10 फ्लैश-कार्ड बनाएँ और PDF के रूप में सहेजें ('मौर्य साम्राज्य.pdf')। तैयार PDF नोट्स खोजने हेतु क्लिक करें। | K16: वेबसाइट पर पढ़ें: drishtiias.com • visionias.in • ncert.nic.in (क्लिक करें) | L16: बिहार विशेष | M16: बिहार – मध्यकालीन एवं औपनिवेशिक इतिहास (भाग 4/5) | N16: विज्ञान-प्रौद्योगिकी, अंतरिक्ष व रक्षा समाचार | O16: आज के विषय पर 50 MCQ (+ उससे संबंधित BPSC PYQ) | P16: कल के नोट्स दोहराएँ (30 मिनट) | Q16: 7.5 | R16: NCERT इतिहास (कक्षा 6-12) • स्पेक्ट्रम आधुनिक भारत • दृष्टि IAS इतिहास नोट्स (हिंदी) • विजन IAS PT365/क्लास नोट्स • BPSC वाला क्लास नोट्स | S16: नवीनतम बिहार आर्थिक सर्वेक्षण व बजट • BPSC वाला बिहार विशेष • दृष्टि IAS बिहार विशेष (हिंदी) • राज्य सरकार के पोर्टल • बिहार सामान्य ज्ञान पुस्तक (लूसेंट/प्रभात) | T16: ▶ दृष्टि IAS | U16: ▶ BPSC वाला | V16: ▶ BPSC वाला | W16: शुरू नहीं हुआ | Y16: 📖 पढ़ें: दृष्टि • विजन • NCERT • जागरण जोश • GKToday
A17: 12 | B17: =सारांश!$B$4+A17-1 -> 46352 | C17: =CHOOSE(WEEKDAY(B17,2),"सोमवार","मंगलवार","बुधवार","गुरुवार","शुक्रवार","शनिवार","रविवार") -> गुरुवार | D17: =IF(A17=1,0,INT((A17-2)/7)+1) -> 2 | E17: =(YEAR(B17)-YEAR(सारांश!$B$4))*12+MONTH(B17)-MONTH(सारांश!$B$4)+IF(DAY(B17)>=DAY(सारांश!$B$4),1,0) -> 1 | F17: चरण 1: आधार निर्माण (प्रथम अध्ययन) | G17: इतिहास | H17: मौर्य साम्राज्य (भाग 2/3) | I17: चंद्रगुप्त, बिंदुसार, अशोक; कलिंग युद्ध व धम्म; अभिलेख; अर्थशास्त्र; मेगस्थनीज; प्रशासन, अर्थव्यवस्था, कला; पतन | J17: पढ़ें: मौर्य साम्राज्य – NCERT इतिहास (कक्षा 6-12) • स्पेक्ट्रम आधुनिक भारत • दृष्टि IAS इतिहास नोट्स (हिंदी)। फिर स्वयं के 1-2 पृष्ठ के नोट्स + 10 फ्लैश-कार्ड बनाएँ और PDF के रूप में सहेजें ('मौर्य साम्राज्य.pdf')। तैयार PDF नोट्स खोजने हेतु क्लिक करें। | K17: वेबसाइट पर पढ़ें: drishtiias.com • visionias.in • ncert.nic.in (क्लिक करें) | L17: बिहार विशेष | M17: बिहार – मध्यकालीन एवं औपनिवेशिक इतिहास (भाग 5/5) | N17: अंतर्राष्ट्रीय संबंध, शिखर सम्मेलन व भारत के पड़ोसी | O17: आज के विषय पर 50 MCQ (+ उससे संबंधित BPSC PYQ) | P17: कल के नोट्स दोहराएँ (30 मिनट) | Q17: 7.5 | R17: NCERT इतिहास (कक्षा 6-12) • स्पेक्ट्रम आधुनिक भारत • दृष्टि IAS इतिहास नोट्स (हिंदी) • विजन IAS PT365/क्लास नोट्स • BPSC वाला क्लास नोट्स | S17: नवीनतम बिहार आर्थिक सर्वेक्षण व बजट • BPSC वाला बिहार विशेष • दृष्टि IAS बिहार विशेष (हिंदी) • राज्य सरकार के पोर्टल • बिहार सामान्य ज्ञान पुस्तक (लूसेंट/प्रभात) | T17: ▶ दृष्टि IAS | U17: ▶ BPSC वाला | V17: ▶ BPSC वाला | W17: शुरू नहीं हुआ | Y17: 📖 पढ़ें: दृष्टि • विजन • NCERT • जागरण जोश • GKToday
A18: 13 | B18: =सारांश!$B$4+A18-1 -> 46353 | C18: =CHOOSE(WEEKDAY(B18,2),"सोमवार","मंगलवार","बुधवार","गुरुवार","शुक्रवार","शनिवार","रविवार") -> शुक्रवार | D18: =IF(A18=1,0,INT((A18-2)/7)+1) -> 2 | E18: =(YEAR(B18)-YEAR(सारांश!$B$4))*12+MONTH(B18)-MONTH(सारांश!$B$4)+IF(DAY(B18)>=DAY(सारांश!$B$4),1,0) -> 1 | F18: चरण 1: आधार निर्माण (प्रथम अध्ययन) | G18: इतिहास | H18: मौर्य साम्राज्य (भाग 3/3) | I18: चंद्रगुप्त, बिंदुसार, अशोक; कलिंग युद्ध व धम्म; अभिलेख; अर्थशास्त्र; मेगस्थनीज; प्रशासन, अर्थव्यवस्था, कला; पतन | J18: पढ़ें: मौर्य साम्राज्य – NCERT इतिहास (कक्षा 6-12) • स्पेक्ट्रम आधुनिक भारत • दृष्टि IAS इतिहास नोट्स (हिंदी)। फिर स्वयं के 1-2 पृष्ठ के नोट्स + 10 फ्लैश-कार्ड बनाएँ और PDF के रूप में सहेजें ('मौर्य साम्राज्य.pdf')। तैयार PDF नोट्स खोजने हेतु क्लिक करें। | K18: वेबसाइट पर पढ़ें: drishtiias.com • visionias.in • ncert.nic.in (क्लिक करें) | L18: बिहार विशेष | M18: बिहार – स्वतंत्रता संग्राम एवं आधुनिक राजनीति (भाग 1/5) | N18: पर्यावरण, योजनाएँ, रिपोर्ट व सूचकांक | O18: आज के विषय पर 50 MCQ (+ उससे संबंधित BPSC PYQ) | P18: कल के नोट्स दोहराएँ (30 मिनट) | Q18: 7.5 | R18: NCERT इतिहास (कक्षा 6-12) • स्पेक्ट्रम आधुनिक भारत • दृष्टि IAS इतिहास नोट्स (हिंदी) • विजन IAS PT365/क्लास नोट्स • BPSC वाला क्लास नोट्स | S18: नवीनतम बिहार आर्थिक सर्वेक्षण व बजट • BPSC वाला बिहार विशेष • दृष्टि IAS बिहार विशेष (हिंदी) • राज्य सरकार के पोर्टल • बिहार सामान्य ज्ञान पुस्तक (लूसेंट/प्रभात) | T18: ▶ दृष्टि IAS | U18: ▶ BPSC वाला | V18: ▶ BPSC वाला | W18: शुरू नहीं हुआ | Y18: 📖 पढ़ें: दृष्टि • विजन • NCERT • जागरण जोश • GKToday
A19: 14 | B19: =सारांश!$B$4+A19-1 -> 46354 | C19: =CHOOSE(WEEKDAY(B19,2),"सोमवार","मंगलवार","बुधवार","गुरुवार","शुक्रवार","शनिवार","रविवार") -> शनिवार | D19: =IF(A19=1,0,INT((A19-2)/7)+1) -> 2 | E19: =(YEAR(B19)-YEAR(सारांश!$B$4))*12+MONTH(B19)-MONTH(सारांश!$B$4)+IF(DAY(B19)>=DAY(सारांश!$B$4),1,0) -> 1 | F19: चरण 1: आधार निर्माण (प्रथम अध्ययन) | G19: इतिहास | H19: मौर्योत्तर काल (शुंग, कुषाण, सातवाहन, संगम) | I19: शुंग व कण्व; हिंद-यूनानी, शक, कुषाण (कनिष्क); सातवाहन; संगम साहित्य व शासन; गांधार व मथुरा कला | J19: पढ़ें: मौर्योत्तर काल (शुंग, कुषाण, सातवाहन, संगम) – NCERT इतिहास (कक्षा 6-12) • स्पेक्ट्रम आधुनिक भारत • दृष्टि IAS इतिहास नोट्स (हिंदी)। फिर स्वयं के 1-2 पृष्ठ के नोट्स + 10 फ्लैश-कार्ड बनाएँ और PDF के रूप में सहेजें ('मौर्योत्तर काल (शुंग, कुषाण,.pdf')। तैयार PDF नोट्स खोजने हेतु क्लिक करें। | K19: वेबसाइट पर पढ़ें: drishtiias.com • visionias.in • ncert.nic.in (क्लिक करें) | L19: बिहार विशेष | M19: बिहार – स्वतंत्रता संग्राम एवं आधुनिक राजनीति (भाग 2/5) | N19: साप्ताहिक करेंट अफेयर्स संकलन + 20 MCQ (दृष्टि / विजन IAS साप्ताहिक) | O19: आज के विषय पर 50 MCQ (+ उससे संबंधित BPSC PYQ) | P19: कल के नोट्स दोहराएँ (30 मिनट) | Q19: 7.5 | R19: NCERT इतिहास (कक्षा 6-12) • स्पेक्ट्रम आधुनिक भारत • दृष्टि IAS इतिहास नोट्स (हिंदी) • विजन IAS PT365/क्लास नोट्स • BPSC वाला क्लास नोट्स | S19: नवीनतम बिहार आर्थिक सर्वेक्षण व बजट • BPSC वाला बिहार विशेष • दृष्टि IAS बिहार विशेष (हिंदी) • राज्य सरकार के पोर्टल • बिहार सामान्य ज्ञान पुस्तक (लूसेंट/प्रभात) | T19: ▶ दृष्टि IAS | U19: ▶ BPSC वाला | V19: ▶ BPSC वाला | W19: शुरू नहीं हुआ | Y19: 📖 पढ़ें: दृष्टि • विजन • NCERT • जागरण जोश • GKToday
A20: 15 | B20: =सारांश!$B$4+A20-1 -> 46355 | C20: =CHOOSE(WEEKDAY(B20,2),"सोमवार","मंगलवार","बुधवार","गुरुवार","शुक्रवार","शनिवार","रविवार") -> रविवार | D20: =IF(A20=1,0,INT((A20-2)/7)+1) -> 2 | E20: =(YEAR(B20)-YEAR(सारांश!$B$4))*12+MONTH(B20)-MONTH(सारांश!$B$4)+IF(DAY(B20)>=DAY(सारांश!$B$4),1,0) -> 1 | F20: चरण 1: आधार निर्माण (प्रथम अध्ययन) | G20: टेस्ट एवं पुनरावृत्ति | H20: साप्ताहिक टेस्ट (100 MCQ, 90 मिनट) + विश्लेषण | I20: इस सप्ताह के विषय दोहराएँ: जैन, बौद्ध एवं अन्य नास्तिक संप्रदाय; मौर्य साम्राज्य; मौर्योत्तर काल (शुंग, कुषाण, सातवाहन, संगम)। त्रुटि-लॉग अद्यतन करें; 20 कमज़ोर बिंदु सूचीबद्ध करें; संक्षिप्त नोट्स दोबारा पढ़ें। | J20: इस सप्ताह के अपने PDF/हस्तलिखित नोट्स दोबारा पढ़ें। उन्हें 1 पृष्ठ के साप्ताहिक सारांश PDF में जोड़ें (त्रुटि-लॉग + 20 कमज़ोर बिंदु)। | K20: वेबसाइट पर पढ़ें: drishtiias.com • visionias.in • pib.gov.in (क्लिक करें) | L20: पुनरावृत्ति | M20: सप्ताह के द्वितीयक/बिहार विषय दोहराएँ + साप्ताहिक करेंट अफेयर्स संकलन | N20: साप्ताहिक करेंट अफेयर्स संकलन (दृष्टि IAS / विजन IAS साप्ताहिक) + 20 MCQ | O20: लक्ष्य अंक: 55%+ (साप्ताहिक शीट में अपना स्कोर दर्ज करें) | P20: पूरे सप्ताह की पुनरावृत्ति (2 घंटे) | Q20: 6 | R20: BPSC वाला / दृष्टि IAS / विजन IAS टेस्ट सीरीज़ • BPSC के PYQ (bpsc.bihar.gov.in) | S20: स्वयं के संक्षिप्त नोट्स • त्रुटि-लॉग • साप्ताहिक करेंट अफेयर्स (दृष्टि / विजन IAS) | T20: ▶ दृष्टि IAS | U20: ▶ BPSC वाला | V20: ▶ BPSC वाला | W20: शुरू नहीं हुआ
A21: 16 | B21: =सारांश!$B$4+A21-1 -> 46356 | C21: =CHOOSE(WEEKDAY(B21,2),"सोमवार","मंगलवार","बुधवार","गुरुवार","शुक्रवार","शनिवार","रविवार") -> सोमवार | D21: =IF(A21=1,0,INT((A21-2)/7)+1) -> 3 | E21: =(YEAR(B21)-YEAR(सारांश!$B$4))*12+MONTH(B21)-MONTH(सारांश!$B$4)+IF(DAY(B21)>=DAY(सारांश!$B$4),1,0) -> 1 | F21: चरण 1: आधार निर्माण (प्रथम अध्ययन) | G21: इतिहास | H21: गुप्त साम्राज्य, हर्षवर्धन एवं पाल वंश (भाग 1/3) | I21: समुद्रगुप्त, चंद्रगुप्त द्वितीय, स्कंदगुप्त; स्वर्ण युग (विज्ञान, कला, साहित्य); हर्षवर्धन व चीनी यात्री; पाल (धर्मपाल, नालंदा, विक्रमशिला) | J21: पढ़ें: गुप्त साम्राज्य, हर्षवर्धन एवं पाल वंश – NCERT इतिहास (कक्षा 6-12) • स्पेक्ट्रम आधुनिक भारत • दृष्टि IAS इतिहास नोट्स (हिंदी)। फिर स्वयं के 1-2 पृष्ठ के नोट्स + 10 फ्लैश-कार्ड बनाएँ और PDF के रूप में सहेजें ('गुप्त साम्राज्य, हर्षवर्धन एवं.pdf')। तैयार PDF नोट्स खोजने हेतु क्लिक करें। | K21: वेबसाइट पर पढ़ें: drishtiias.com • visionias.in • ncert.nic.in (क्लिक करें) | L21: बिहार विशेष | M21: बिहार – स्वतंत्रता संग्राम एवं आधुनिक राजनीति (भाग 3/5) | N21: बिहार समाचार (प्रभात खबर / दैनिक जागरण) + दृष्टि IAS दैनिक करेंट अफेयर्स | O21: आज के विषय पर 50 MCQ (+ उससे संबंधित BPSC PYQ) | P21: कल के नोट्स दोहराएँ (30 मिनट) | Q21: 7.5 | R21: NCERT इतिहास (कक्षा 6-12) • स्पेक्ट्रम आधुनिक भारत • दृष्टि IAS इतिहास नोट्स (हिंदी) • विजन IAS PT365/क्लास नोट्स • BPSC वाला क्लास नोट्स | S21: नवीनतम बिहार आर्थिक सर्वेक्षण व बजट • BPSC वाला बिहार विशेष • दृष्टि IAS बिहार विशेष (हिंदी) • राज्य सरकार के पोर्टल • बिहार सामान्य ज्ञान पुस्तक (लूसेंट/प्रभात) | T21: ▶ दृष्टि IAS | U21: ▶ BPSC वाला | V21: ▶ BPSC वाला | W21: शुरू नहीं हुआ | Y21: 📖 पढ़ें: दृष्टि • विजन • NCERT • जागरण जोश • GKToday
A22: 17 | B22: =सारांश!$B$4+A22-1 -> 46357 | C22: =CHOOSE(WEEKDAY(B22,2),"सोमवार","मंगलवार","बुधवार","गुरुवार","शुक्रवार","शनिवार","रविवार") -> मंगलवार | D22: =IF(A22=1,0,INT((A22-2)/7)+1) -> 3 | E22: =(YEAR(B22)-YEAR(सारांश!$B$4))*12+MONTH(B22)-MONTH(सारांश!$B$4)+IF(DAY(B22)>=DAY(सारांश!$B$4),1,0) -> 1 | F22: चरण 1: आधार निर्माण (प्रथम अध्ययन) | G22: इतिहास | H22: गुप्त साम्राज्य, हर्षवर्धन एवं पाल वंश (भाग 2/3) | I22: समुद्रगुप्त, चंद्रगुप्त द्वितीय, स्कंदगुप्त; स्वर्ण युग (विज्ञान, कला, साहित्य); हर्षवर्धन व चीनी यात्री; पाल (धर्मपाल, नालंदा, विक्रमशिला) | J22: पढ़ें: गुप्त साम्राज्य, हर्षवर्धन एवं पाल वंश – NCERT इतिहास (कक्षा 6-12) • स्पेक्ट्रम आधुनिक भारत • दृष्टि IAS इतिहास नोट्स (हिंदी)। फिर स्वयं के 1-2 पृष्ठ के नोट्स + 10 फ्लैश-कार्ड बनाएँ और PDF के रूप में सहेजें ('गुप्त साम्राज्य, हर्षवर्धन एवं.pdf')। तैयार PDF नोट्स खोजने हेतु क्लिक करें। | K22: वेबसाइट पर पढ़ें: drishtiias.com • visionias.in • ncert.nic.in (क्लिक करें) | L22: बिहार विशेष | M22: बिहार – स्वतंत्रता संग्राम एवं आधुनिक राजनीति (भाग 4/5) | N22: राजव्यवस्था, शासन व अर्थव्यवस्था के समाचार (द हिंदू / दृष्टि IAS) | O22: आज के विषय पर 50 MCQ (+ उससे संबंधित BPSC PYQ) | P22: कल के नोट्स दोहराएँ (30 मिनट) | Q22: 7.5 | R22: NCERT इतिहास (कक्षा 6-12) • स्पेक्ट्रम आधुनिक भारत • दृष्टि IAS इतिहास नोट्स (हिंदी) • विजन IAS PT365/क्लास नोट्स • BPSC वाला क्लास नोट्स | S22: नवीनतम बिहार आर्थिक सर्वेक्षण व बजट • BPSC वाला बिहार विशेष • दृष्टि IAS बिहार विशेष (हिंदी) • राज्य सरकार के पोर्टल • बिहार सामान्य ज्ञान पुस्तक (लूसेंट/प्रभात) | T22: ▶ दृष्टि IAS | U22: ▶ BPSC वाला | V22: ▶ BPSC वाला | W22: शुरू नहीं हुआ | Y22: 📖 पढ़ें: दृष्टि • विजन • NCERT • जागरण जोश • GKToday
